Workbook
Name 清单_付款主体: 选项!$A$2:$A$4
Name 清单_物流商: 供应商列表!$A$4:$A$25
Name 清单_费用归属: 选项!$C$2:$C$14
Name 清单_业务线: 选项!$B$2:$B$11
Name 清单_结算类型: 选项!$E$2:$E$3
Name 清单_状态: 选项!$G$2:$G$7

Sheet 填表说明
A1: 物流费用计提表模板 v2.1 —— 使用说明(重构方案 v2.1 配套样表)
A3: 六张表分工
A4: ① 填表说明 | B4: 本页。物流部只需要看本页+填② 计提明细表。
A5: ② 计提明细表 | B5: 唯一手填。每行一笔费用:选 付款主体/物流商/费用归属/业务线 + 填含税金额(黄格)。税率/未税/税额/全称/摘要 全部自动,请勿改灰格。右侧浅绿5列=做账维度(财务看/改,物流部不用管)。
A6: ③ 做账去向表 | B6: 财务/审批视角:本月费用准备做到 哪个科目×哪个业务线×哪个部门,全公式自动按明细表维度汇总;行=历史账证实证的维度组合。不用填。
A7: ④ 供应商列表 | B7: 物流商身份+渠道+13类费用归属税率矩阵。由财务工具按月签发快照,物流部勿改;缺物流商请联系财务在工具里新增。
A8: ⑤ 物流商费用汇总表 | B8: 全自动汇总:各主体×税率(9/6/13%)+含税合计+五档进度。不用填。
A9: ⑥ 费用归属表(快照) | B9: 财务口径:13类费用归属各自怎么做账。由财务工具维护,此处为只读快照。
A11: 13 类费用归属怎么选(核心,每类科目唯一)
A12: 销售出库费用 | B12: 各业务线销售发货运费;装卸费没单列在账单里时,含在这里,不用拆。
A13: 成品入库费用 / 原料入库费用 | B13: 入库方向按料件分:代工厂成品回仓/电商仓成品入仓=成品;孝感工厂采购到付/小料原料=原料。拿不准问财务。
A14: 成品仓储费用 / 原料仓储费用 | B14: 外仓仓储费按存的是成品还是原料分。
A15: 成品调拨费用 / 原料调拨费用 | B15: 仓与仓之间转运。
A16: 出库/成品入库/原料入库 装卸费用 | B16: 仅当账单把装卸费单独列一行时才用(目前只有天鹰);平时装卸含在销售出库里。
A17: 研发设备采购 | B17: 研发外购、研发中试的运费。
A18: 设备调拨费用 | B18: 设备转移、设备仓租。科目部门由财务录入时按每笔需求定,物流部只管填金额+业务描述(写清什么设备、从哪到哪、给谁用)。
A19: 其它 | B19: 捐赠/报废、原料销售运费等,选它并在备注里写清楚。
A21: 特殊口径
A22: 山姆业务 | B22: 不用单独标山姆:山姆鲜食→业务线选「鲜食」;山姆零售→选「山姆零售」。系统自动挂 TO C。
A23: 海外业务 | B23: 业务线选「海外」,并在「业务描述」写明 到岸前/到岸后、自产/外采——这决定付款主体归属。
A24: kikiherb | B24: 暂选 业务线=零售,业务描述写 kikiherb(口径确认后模板会更新)。
A25: 非月结 | B25: 结算类型选「非月结」并填经办人(货拉拉、临时用车等)。
A27: 颜色图例
A28: 黄底 | B28: 手填·唯一必填数字(含税金额)
A29: 浅黄底 | B29: 手填·下拉选择或选填文字
A30: 灰底 | B30: 公式自动,勿手改(表已锁定保护)
A31: 蓝底 | B31: 财务工具回填(凭证号/定稿金额),勿手改
A32: 橙底 | B32: 税率特例(与该物流商默认档不同,如易风达/极鲜达仓储6%)
A33: 浅绿底 | B33: 做账维度区(明细表右侧5列:借方科目/部门/费用项目/产品分类/产品项目)——按账证实证规则公式预填,财务可直接改格子,工作台以列值为准;物流部不用管
A34: 绿底 | B34: 财务口径快照,物流部不用管
A36: 提交 | B36: 每月底把本文件发给财务核算。文件名请保持「物流费用计提表_2026-MM」。

Sheet 计提明细表
A1: 物流费用计提 · 计提明细表(唯一手填表) 账期 2026-07 [v2.1 样表·13类费用归属闭环]
A2: 填表须知:黄底=手填(含税金额唯一必填数字);浅黄=下拉/选填;灰底=公式自动(已锁定);蓝底=工具回填;浅绿=做账维度(公式按账证实证规则预填,财务可直接改,工具以列值为准)。一行一笔费用=一张凭证;示例行为 2026-05 真数据机翻,正式使用时清空。 | T2: ── 做账维度区(财务看/改,物流部不用管)──
A3: 账期 | B3: 付款主体 | C3: 物流商简称 | D3: 费用归属 | E3: 业务线 | F3: 业务描述 (摘要用/来源·选填) | G3: 结算类型 | H3: 经办人 | I3: 含税金额 | J3: 税率 | K3: 未税 | L3: 税额 | M3: 物流商全称 | N3: 摘要(公式自动) | O3: 计提凭证号 | P3: 对账定稿金额 | Q3: 计提差异 | R3: 差异处理 | S3: 备注 | T3: 借方科目 | U3: 部门 | V3: 费用项目 | W3: 产品分类 (业务线维度) | X3: 产品项目 (TO C等)
A4: 2026-07 | B4: 深圳星期零 | C4: 顺丰冷运 | D4: 销售出库费用 | E4: 豆蛋制品 | G4: 月结 | I4: 270 | J4: =IFERROR(INDEX(供应商列表!$F$4:$R$25,MATCH(C4,供应商列表!$A$4:$A$25,0),MATCH(D4,供应商列表!$F$3:$R$3,0)),"") | K4: =IFERROR(ROUND(I4/(1+J4),2),"") | L4: =IFERROR(I4-K4,"") | M4: =IFERROR(INDEX(供应商列表!$B$4:$B$25,MATCH(C4,供应商列表!$A$4:$A$25,0)),"") | N4: ="计提"&M4&(MID(A4,6,2)*1)&"月"&IFERROR(INDEX(供应商列表!$E$4:$E$25,MATCH(C4,供应商列表!$A$4:$A$25,0)),"线下")&IF(F4<>"",F4,IF(OR(E4="—",E4=""),"",E4))&IFERROR(INDEX('费用归属表（快照）'!$F$4:$F$16,MATCH(D4,'费用归属表（快照）'!$A$4:$A$16,0)),"") | Q4: =IF(P4="","",P4-I4) | T4: =IF(D4="","",IFERROR(INDEX('费用归属表（快照）'!$C$4:$C$16,MATCH(D4,'费用归属表（快照）'!$A$4:$A$16,0)),"")) | U4: =IF(D4="","",IF(AND(D4="销售出库费用",B4="深圳星期九"),"永续供应中心 0010401",IF(AND(D4="原料入库费用",E4="小料"),"茶饮小料部 0030902",IFERROR(INDEX('费用归属表（快照）'!$D$4:$D$16,MATCH(D4,'费用归属表（快照）'!$A$4:$A$16,0)),"")))) | V4: =IF(D4="","",IFERROR(INDEX('费用归属表（快照）'!$B$4:$B$16,MATCH(D4,'费用归属表（快照）'!$A$4:$A$16,0)),"")) | W4: =IF(OR(E4="",AND(LEFT(T4,4)<>"6601",LEFT(T4,4)<>"6401")),"",IFERROR(IF(INDEX(选项!$I$2:$I$11,MATCH(E4,选项!$H$2:$H$11,0))="","",INDEX(选项!$I$2:$I$11,MATCH(E4,选项!$H$2:$H$11,0))),"")) | X4: =IF(OR(E4="",AND(LEFT(T4,4)<>"6601",LEFT(T4,4)<>"6401")),"",IFERROR(IF(INDEX(选项!$J$2:$J$11,MATCH(E4,选项!$H$2:$H$11,0))="","",INDEX(选项!$J$2:$J$11,MATCH(E4,选项!$H$2:$H$11,0))),""))
A5: 2026-07 | B5: 深圳星期零 | C5: 顺丰冷运 | D5: 原料入库费用 | E5: 小料 | F5: 小料 | G5: 月结 | I5: 1125 | J5: =IFERROR(INDEX(供应商列表!$F$4:$R$25,MATCH(C5,供应商列表!$A$4:$A$25,0),MATCH(D5,供应商列表!$F$3:$R$3,0)),"") | K5: =IFERROR(ROUND(I5/(1+J5),2),"") | L5: =IFERROR(I5-K5,"") | M5: =IFERROR(INDEX(供应商列表!$B$4:$B$25,MATCH(C5,供应商列表!$A$4:$A$25,0)),"") | N5: ="计提"&M5&(MID(A5,6,2)*1)&"月"&IFERROR(INDEX(供应商列表!$E$4:$E$25,MATCH(C5,供应商列表!$A$4:$A$25,0)),"线下")&IF(F5<>"",F5,IF(OR(E5="—",E5=""),"",E5))&IFERROR(INDEX('费用归属表（快照）'!$F$4:$F$16,MATCH(D5,'费用归属表（快照）'!$A$4:$A$16,0)),"") | Q5: =IF(P5="","",P5-I5) | T5: =IF(D5="","",IFERROR(INDEX('费用归属表（快照）'!$C$4:$C$16,MATCH(D5,'费用归属表（快照）'!$A$4:$A$16,0)),"")) | U5: =IF(D5="","",IF(AND(D5="销售出库费用",B5="深圳星期九"),"永续供应中心 0010401",IF(AND(D5="原料入库费用",E5="小料"),"茶饮小料部 0030902",IFERROR(INDEX('费用归属表（快照）'!$D$4:$D$16,MATCH(D5,'费用归属表（快照）'!$A$4:$A$16,0)),"")))) | V5: =IF(D5="","",IFERROR(INDEX('费用归属表（快照）'!$B$4:$B$16,MATCH(D5,'费用归属表（快照）'!$A$4:$A$16,0)),"")) | W5: =IF(OR(E5="",AND(LEFT(T5,4)<>"6601",LEFT(T5,4)<>"6401")),"",IFERROR(IF(INDEX(选项!$I$2:$I$11,MATCH(E5,选项!$H$2:$H$11,0))="","",INDEX(选项!$I$2:$I$11,MATCH(E5,选项!$H$2:$H$11,0))),"")) | X5: =IF(OR(E5="",AND(LEFT(T5,4)<>"6601",LEFT(T5,4)<>"6401")),"",IFERROR(IF(INDEX(选项!$J$2:$J$11,MATCH(E5,选项!$H$2:$H$11,0))="","",INDEX(选项!$J$2:$J$11,MATCH(E5,选项!$H$2:$H$11,0))),""))
A6: 2026-07 | B6: 深圳星期零 | C6: 顺丰冷运 | D6: 销售出库费用 | E6: 小料 | G6: 月结 | I6: 2220 | J6: =IFERROR(INDEX(供应商列表!$F$4:$R$25,MATCH(C6,供应商列表!$A$4:$A$25,0),MATCH(D6,供应商列表!$F$3:$R$3,0)),"") | K6: =IFERROR(ROUND(I6/(1+J6),2),"") | L6: =IFERROR(I6-K6,"") | M6: =IFERROR(INDEX(供应商列表!$B$4:$B$25,MATCH(C6,供应商列表!$A$4:$A$25,0)),"") | N6: ="计提"&M6&(MID(A6,6,2)*1)&"月"&IFERROR(INDEX(供应商列表!$E$4:$E$25,MATCH(C6,供应商列表!$A$4:$A$25,0)),"线下")&IF(F6<>"",F6,IF(OR(E6="—",E6=""),"",E6))&IFERROR(INDEX('费用归属表（快照）'!$F$4:$F$16,MATCH(D6,'费用归属表（快照）'!$A$4:$A$16,0)),"") | Q6: =IF(P6="","",P6-I6) | T6: =IF(D6="","",IFERROR(INDEX('费用归属表（快照）'!$C$4:$C$16,MATCH(D6,'费用归属表（快照）'!$A$4:$A$16,0)),"")) | U6: =IF(D6="","",IF(AND(D6="销售出库费用",B6="深圳星期九"),"永续供应中心 0010401",IF(AND(D6="原料入库费用",E6="小料"),"茶饮小料部 0030902",IFERROR(INDEX('费用归属表（快照）'!$D$4:$D$16,MATCH(D6,'费用归属表（快照）'!$A$4:$A$16,0)),"")))) | V6: =IF(D6="","",IFERROR(INDEX('费用归属表（快照）'!$B$4:$B$16,MATCH(D6,'费用归属表（快照）'!$A$4:$A$16,0)),"")) | W6: =IF(OR(E6="",AND(LEFT(T6,4)<>"6601",LEFT(T6,4)<>"6401")),"",IFERROR(IF(INDEX(选项!$I$2:$I$11,MATCH(E6,选项!$H$2:$H$11,0))="","",INDEX(选项!$I$2:$I$11,MATCH(E6,选项!$H$2:$H$11,0))),"")) | X6: =IF(OR(E6="",AND(LEFT(T6,4)<>"6601",LEFT(T6,4)<>"6401")),"",IFERROR(IF(INDEX(选项!$J$2:$J$11,MATCH(E6,选项!$H$2:$H$11,0))="","",INDEX(选项!$J$2:$J$11,MATCH(E6,选项!$H$2:$H$11,0))),""))
A7: 2026-07 | B7: 深圳星期零 | C7: 顺丰速运 | D7: 销售出库费用 | E7: 植物肉 | G7: 月结 | I7: 384 | J7: =IFERROR(INDEX(供应商列表!$F$4:$R$25,MATCH(C7,供应商列表!$A$4:$A$25,0),MATCH(D7,供应商列表!$F$3:$R$3,0)),"") | K7: =IFERROR(ROUND(I7/(1+J7),2),"") | L7: =IFERROR(I7-K7,"") | M7: =IFERROR(INDEX(供应商列表!$B$4:$B$25,MATCH(C7,供应商列表!$A$4:$A$25,0)),"") | N7: ="计提"&M7&(MID(A7,6,2)*1)&"月"&IFERROR(INDEX(供应商列表!$E$4:$E$25,MATCH(C7,供应商列表!$A$4:$A$25,0)),"线下")&IF(F7<>"",F7,IF(OR(E7="—",E7=""),"",E7))&IFERROR(INDEX('费用归属表（快照）'!$F$4:$F$16,MATCH(D7,'费用归属表（快照）'!$A$4:$A$16,0)),"") | Q7: =IF(P7="","",P7-I7) | T7: =IF(D7="","",IFERROR(INDEX('费用归属表（快照）'!$C$4:$C$16,MATCH(D7,'费用归属表（快照）'!$A$4:$A$16,0)),"")) | U7: =IF(D7="","",IF(AND(D7="销售出库费用",B7="深圳星期九"),"永续供应中心 0010401",IF(AND(D7="原料入库费用",E7="小料"),"茶饮小料部 0030902",IFERROR(INDEX('费用归属表（快照）'!$D$4:$D$16,MATCH(D7,'费用归属表（快照）'!$A$4:$A$16,0)),"")))) | V7: =IF(D7="","",IFERROR(INDEX('费用归属表（快照）'!$B$4:$B$16,MATCH(D7,'费用归属表（快照）'!$A$4:$A$16,0)),"")) | W7: =IF(OR(E7="",AND(LEFT(T7,4)<>"6601",LEFT(T7,4)<>"6401")),"",IFERROR(IF(INDEX(选项!$I$2:$I$11,MATCH(E7,选项!$H$2:$H$11,0))="","",INDEX(选项!$I$2:$I$11,MATCH(E7,选项!$H$2:$H$11,0))),"")) | X7: =IF(OR(E7="",AND(LEFT(T7,4)<>"6601",LEFT(T7,4)<>"6401")),"",IFERROR(IF(INDEX(选项!$J$2:$J$11,MATCH(E7,选项!$H$2:$H$11,0))="","",INDEX(选项!$J$2:$J$11,MATCH(E7,选项!$H$2:$H$11,0))),""))
A8: 2026-07 | B8: 深圳星期零 | C8: 顺丰速运 | D8: 销售出库费用 | E8: 鲜食 | G8: 月结 | I8: 66 | J8: =IFERROR(INDEX(供应商列表!$F$4:$R$25,MATCH(C8,供应商列表!$A$4:$A$25,0),MATCH(D8,供应商列表!$F$3:$R$3,0)),"") | K8: =IFERROR(ROUND(I8/(1+J8),2),"") | L8: =IFERROR(I8-K8,"") | M8: =IFERROR(INDEX(供应商列表!$B$4:$B$25,MATCH(C8,供应商列表!$A$4:$A$25,0)),"") | N8: ="计提"&M8&(MID(A8,6,2)*1)&"月"&IFERROR(INDEX(供应商列表!$E$4:$E$25,MATCH(C8,供应商列表!$A$4:$A$25,0)),"线下")&IF(F8<>"",F8,IF(OR(E8="—",E8=""),"",E8))&IFERROR(INDEX('费用归属表（快照）'!$F$4:$F$16,MATCH(D8,'费用归属表（快照）'!$A$4:$A$16,0)),"") | Q8: =IF(P8="","",P8-I8) | T8: =IF(D8="","",IFERROR(INDEX('费用归属表（快照）'!$C$4:$C$16,MATCH(D8,'费用归属表（快照）'!$A$4:$A$16,0)),"")) | U8: =IF(D8="","",IF(AND(D8="销售出库费用",B8="深圳星期九"),"永续供应中心 0010401",IF(AND(D8="原料入库费用",E8="小料"),"茶饮小料部 0030902",IFERROR(INDEX('费用归属表（快照）'!$D$4:$D$16,MATCH(D8,'费用归属表（快照）'!$A$4:$A$16,0)),"")))) | V8: =IF(D8="","",IFERROR(INDEX('费用归属表（快照）'!$B$4:$B$16,MATCH(D8,'费用归属表（快照）'!$A$4:$A$16,0)),"")) | W8: =IF(OR(E8="",AND(LEFT(T8,4)<>"6601",LEFT(T8,4)<>"6401")),"",IFERROR(IF(INDEX(选项!$I$2:$I$11,MATCH(E8,选项!$H$2:$H$11,0))="","",INDEX(选项!$I$2:$I$11,MATCH(E8,选项!$H$2:$H$11,0))),"")) | X8: =IF(OR(E8="",AND(LEFT(T8,4)<>"6601",LEFT(T8,4)<>"6401")),"",IFERROR(IF(INDEX(选项!$J$2:$J$11,MATCH(E8,选项!$H$2:$H$11,0))="","",INDEX(选项!$J$2:$J$11,MATCH(E8,选项!$H$2:$H$11,0))),""))
A9: 2026-07 | B9: 深圳星期零 | C9: 顺丰速运 | D9: 销售出库费用 | E9: 豆蛋制品 | G9: 月结 | I9: 268 | J9: =IFERROR(INDEX(供应商列表!$F$4:$R$25,MATCH(C9,供应商列表!$A$4:$A$25,0),MATCH(D9,供应商列表!$F$3:$R$3,0)),"") | K9: =IFERROR(ROUND(I9/(1+J9),2),"") | L9: =IFERROR(I9-K9,"") | M9: =IFERROR(INDEX(供应商列表!$B$4:$B$25,MATCH(C9,供应商列表!$A$4:$A$25,0)),"") | N9: ="计提"&M9&(MID(A9,6,2)*1)&"月"&IFERROR(INDEX(供应商列表!$E$4:$E$25,MATCH(C9,供应商列表!$A$4:$A$25,0)),"线下")&IF(F9<>"",F9,IF(OR(E9="—",E9=""),"",E9))&IFERROR(INDEX('费用归属表（快照）'!$F$4:$F$16,MATCH(D9,'费用归属表（快照）'!$A$4:$A$16,0)),"") | Q9: =IF(P9="","",P9-I9) | T9: =IF(D9="","",IFERROR(INDEX('费用归属表（快照）'!$C$4:$C$16,MATCH(D9,'费用归属表（快照）'!$A$4:$A$16,0)),"")) | U9: =IF(D9="","",IF(AND(D9="销售出库费用",B9="深圳星期九"),"永续供应中心 0010401",IF(AND(D9="原料入库费用",E9="小料"),"茶饮小料部 0030902",IFERROR(INDEX('费用归属表（快照）'!$D$4:$D$16,MATCH(D9,'费用归属表（快照）'!$A$4:$A$16,0)),"")))) | V9: =IF(D9="","",IFERROR(INDEX('费用归属表（快照）'!$B$4:$B$16,MATCH(D9,'费用归属表（快照）'!$A$4:$A$16,0)),"")) | W9: =IF(OR(E9="",AND(LEFT(T9,4)<>"6601",LEFT(T9,4)<>"6401")),"",IFERROR(IF(INDEX(选项!$I$2:$I$11,MATCH(E9,选项!$H$2:$H$11,0))="","",INDEX(选项!$I$2:$I$11,MATCH(E9,选项!$H$2:$H$11,0))),"")) | X9: =IF(OR(E9="",AND(LEFT(T9,4)<>"6601",LEFT(T9,4)<>"6401")),"",IFERROR(IF(INDEX(选项!$J$2:$J$11,MATCH(E9,选项!$H$2:$H$11,0))="","",INDEX(选项!$J$2:$J$11,MATCH(E9,选项!$H$2:$H$11,0))),""))
A10: 2026-07 | B10: 深圳星期零 | C10: 顺丰速运 | D10: 销售出库费用 | E10: 零售 | G10: 月结 | I10: 175 | J10: =IFERROR(INDEX(供应商列表!$F$4:$R$25,MATCH(C10,供应商列表!$A$4:$A$25,0),MATCH(D10,供应商列表!$F$3:$R$3,0)),"") | K10: =IFERROR(ROUND(I10/(1+J10),2),"") | L10: =IFERROR(I10-K10,"") | M10: =IFERROR(INDEX(供应商列表!$B$4:$B$25,MATCH(C10,供应商列表!$A$4:$A$25,0)),"") | N10: ="计提"&M10&(MID(A10,6,2)*1)&"月"&IFERROR(INDEX(供应商列表!$E$4:$E$25,MATCH(C10,供应商列表!$A$4:$A$25,0)),"线下")&IF(F10<>"",F10,IF(OR(E10="—",E10=""),"",E10))&IFERROR(INDEX('费用归属表（快照）'!$F$4:$F$16,MATCH(D10,'费用归属表（快照）'!$A$4:$A$16,0)),"") | Q10: =IF(P10="","",P10-I10) | T10: =IF(D10="","",IFERROR(INDEX('费用归属表（快照）'!$C$4:$C$16,MATCH(D10,'费用归属表（快照）'!$A$4:$A$16,0)),"")) | U10: =IF(D10="","",IF(AND(D10="销售出库费用",B10="深圳星期九"),"永续供应中心 0010401",IF(AND(D10="原料入库费用",E10="小料"),"茶饮小料部 0030902",IFERROR(INDEX('费用归属表（快照）'!$D$4:$D$16,MATCH(D10,'费用归属表（快照）'!$A$4:$A$16,0)),"")))) | V10: =IF(D10="","",IFERROR(INDEX('费用归属表（快照）'!$B$4:$B$16,MATCH(D10,'费用归属表（快照）'!$A$4:$A$16,0)),"")) | W10: =IF(OR(E10="",AND(LEFT(T10,4)<>"6601",LEFT(T10,4)<>"6401")),"",IFERROR(IF(INDEX(选项!$I$2:$I$11,MATCH(E10,选项!$H$2:$H$11,0))="","",INDEX(选项!$I$2:$I$11,MATCH(E10,选项!$H$2:$H$11,0))),"")) | X10: =IF(OR(E10="",AND(LEFT(T10,4)<>"6601",LEFT(T10,4)<>"6401")),"",IFERROR(IF(INDEX(选项!$J$2:$J$11,MATCH(E10,选项!$H$2:$H$11,0))="","",INDEX(选项!$J$2:$J$11,MATCH(E10,选项!$H$2:$H$11,0))),""))
A11: 2026-07 | B11: 深圳星期零 | C11: 顺丰速运 | D11: 销售出库费用 | E11: 小料 | G11: 月结 | I11: 612 | J11: =IFERROR(INDEX(供应商列表!$F$4:$R$25,MATCH(C11,供应商列表!$A$4:$A$25,0),MATCH(D11,供应商列表!$F$3:$R$3,0)),"") | K11: =IFERROR(ROUND(I11/(1+J11),2),"") | L11: =IFERROR(I11-K11,"") | M11: =IFERROR(INDEX(供应商列表!$B$4:$B$25,MATCH(C11,供应商列表!$A$4:$A$25,0)),"") | N11: ="计提"&M11&(MID(A11,6,2)*1)&"月"&IFERROR(INDEX(供应商列表!$E$4:$E$25,MATCH(C11,供应商列表!$A$4:$A$25,0)),"线下")&IF(F11<>"",F11,IF(OR(E11="—",E11=""),"",E11))&IFERROR(INDEX('费用归属表（快照）'!$F$4:$F$16,MATCH(D11,'费用归属表（快照）'!$A$4:$A$16,0)),"") | Q11: =IF(P11="","",P11-I11) | T11: =IF(D11="","",IFERROR(INDEX('费用归属表（快照）'!$C$4:$C$16,MATCH(D11,'费用归属表（快照）'!$A$4:$A$16,0)),"")) | U11: =IF(D11="","",IF(AND(D11="销售出库费用",B11="深圳星期九"),"永续供应中心 0010401",IF(AND(D11="原料入库费用",E11="小料"),"茶饮小料部 0030902",IFERROR(INDEX('费用归属表（快照）'!$D$4:$D$16,MATCH(D11,'费用归属表（快照）'!$A$4:$A$16,0)),"")))) | V11: =IF(D11="","",IFERROR(INDEX('费用归属表（快照）'!$B$4:$B$16,MATCH(D11,'费用归属表（快照）'!$A$4:$A$16,0)),"")) | W11: =IF(OR(E11="",AND(LEFT(T11,4)<>"6601",LEFT(T11,4)<>"6401")),"",IFERROR(IF(INDEX(选项!$I$2:$I$11,MATCH(E11,选项!$H$2:$H$11,0))="","",INDEX(选项!$I$2:$I$11,MATCH(E11,选项!$H$2:$H$11,0))),"")) | X11: =IF(OR(E11="",AND(LEFT(T11,4)<>"6601",LEFT(T11,4)<>"6401")),"",IFERROR(IF(INDEX(选项!$J$2:$J$11,MATCH(E11,选项!$H$2:$H$11,0))="","",INDEX(选项!$J$2:$J$11,MATCH(E11,选项!$H$2:$H$11,0))),""))
A12: 2026-07 | B12: 深圳星期零 | C12: 跨越物流 | D12: 销售出库费用 | E12: 植物肉 | G12: 月结 | I12: 1199.55 | J12: =IFERROR(INDEX(供应商列表!$F$4:$R$25,MATCH(C12,供应商列表!$A$4:$A$25,0),MATCH(D12,供应商列表!$F$3:$R$3,0)),"") | K12: =IFERROR(ROUND(I12/(1+J12),2),"") | L12: =IFERROR(I12-K12,"") | M12: =IFERROR(INDEX(供应商列表!$B$4:$B$25,MATCH(C12,供应商列表!$A$4:$A$25,0)),"") | N12: ="计提"&M12&(MID(A12,6,2)*1)&"月"&IFERROR(INDEX(供应商列表!$E$4:$E$25,MATCH(C12,供应商列表!$A$4:$A$25,0)),"线下")&IF(F12<>"",F12,IF(OR(E12="—",E12=""),"",E12))&IFERROR(INDEX('费用归属表（快照）'!$F$4:$F$16,MATCH(D12,'费用归属表（快照）'!$A$4:$A$16,0)),"") | Q12: =IF(P12="","",P12-I12) | T12: =IF(D12="","",IFERROR(INDEX('费用归属表（快照）'!$C$4:$C$16,MATCH(D12,'费用归属表（快照）'!$A$4:$A$16,0)),"")) | U12: =IF(D12="","",IF(AND(D12="销售出库费用",B12="深圳星期九"),"永续供应中心 0010401",IF(AND(D12="原料入库费用",E12="小料"),"茶饮小料部 0030902",IFERROR(INDEX('费用归属表（快照）'!$D$4:$D$16,MATCH(D12,'费用归属表（快照）'!$A$4:$A$16,0)),"")))) | V12: =IF(D12="","",IFERROR(INDEX('费用归属表（快照）'!$B$4:$B$16,MATCH(D12,'费用归属表（快照）'!$A$4:$A$16,0)),"")) | W12: =IF(OR(E12="",AND(LEFT(T12,4)<>"6601",LEFT(T12,4)<>"6401")),"",IFERROR(IF(INDEX(选项!$I$2:$I$11,MATCH(E12,选项!$H$2:$H$11,0))="","",INDEX(选项!$I$2:$I$11,MATCH(E12,选项!$H$2:$H$11,0))),"")) | X12: =IF(OR(E12="",AND(LEFT(T12,4)<>"6601",LEFT(T12,4)<>"6401")),"",IFERROR(IF(INDEX(选项!$J$2:$J$11,MATCH(E12,选项!$H$2:$H$11,0))="","",INDEX(选项!$J$2:$J$11,MATCH(E12,选项!$H$2:$H$11,0))),""))
A13: 2026-07 | B13: 深圳星期零 | C13: 跨越物流 | D13: 销售出库费用 | E13: 零售 | G13: 月结 | I13: 195.55 | J13: =IFERROR(INDEX(供应商列表!$F$4:$R$25,MATCH(C13,供应商列表!$A$4:$A$25,0),MATCH(D13,供应商列表!$F$3:$R$3,0)),"") | K13: =IFERROR(ROUND(I13/(1+J13),2),"") | L13: =IFERROR(I13-K13,"") | M13: =IFERROR(INDEX(供应商列表!$B$4:$B$25,MATCH(C13,供应商列表!$A$4:$A$25,0)),"") | N13: ="计提"&M13&(MID(A13,6,2)*1)&"月"&IFERROR(INDEX(供应商列表!$E$4:$E$25,MATCH(C13,供应商列表!$A$4:$A$25,0)),"线下")&IF(F13<>"",F13,IF(OR(E13="—",E13=""),"",E13))&IFERROR(INDEX('费用归属表（快照）'!$F$4:$F$16,MATCH(D13,'费用归属表（快照）'!$A$4:$A$16,0)),"") | Q13: =IF(P13="","",P13-I13) | T13: =IF(D13="","",IFERROR(INDEX('费用归属表（快照）'!$C$4:$C$16,MATCH(D13,'费用归属表（快照）'!$A$4:$A$16,0)),"")) | U13: =IF(D13="","",IF(AND(D13="销售出库费用",B13="深圳星期九"),"永续供应中心 0010401",IF(AND(D13="原料入库费用",E13="小料"),"茶饮小料部 0030902",IFERROR(INDEX('费用归属表（快照）'!$D$4:$D$16,MATCH(D13,'费用归属表（快照）'!$A$4:$A$16,0)),"")))) | V13: =IF(D13="","",IFERROR(INDEX('费用归属表（快照）'!$B$4:$B$16,MATCH(D13,'费用归属表（快照）'!$A$4:$A$16,0)),"")) | W13: =IF(OR(E13="",AND(LEFT(T13,4)<>"6601",LEFT(T13,4)<>"6401")),"",IFERROR(IF(INDEX(选项!$I$2:$I$11,MATCH(E13,选项!$H$2:$H$11,0))="","",INDEX(选项!$I$2:$I$11,MATCH(E13,选项!$H$2:$H$11,0))),"")) | X13: =IF(OR(E13="",AND(LEFT(T13,4)<>"6601",LEFT(T13,4)<>"6401")),"",IFERROR(IF(INDEX(选项!$J$2:$J$11,MATCH(E13,选项!$H$2:$H$11,0))="","",INDEX(选项!$J$2:$J$11,MATCH(E13,选项!$H$2:$H$11,0))),""))
A14: 2026-07 | B14: 深圳星期零 | C14: 跨越物流 | D14: 销售出库费用 | E14: 小料 | G14: 月结 | I14: 421.56 | J14: =IFERROR(INDEX(供应商列表!$F$4:$R$25,MATCH(C14,供应商列表!$A$4:$A$25,0),MATCH(D14,供应商列表!$F$3:$R$3,0)),"") | K14: =IFERROR(ROUND(I14/(1+J14),2),"") | L14: =IFERROR(I14-K14,"") | M14: =IFERROR(INDEX(供应商列表!$B$4:$B$25,MATCH(C14,供应商列表!$A$4:$A$25,0)),"") | N14: ="计提"&M14&(MID(A14,6,2)*1)&"月"&IFERROR(INDEX(供应商列表!$E$4:$E$25,MATCH(C14,供应商列表!$A$4:$A$25,0)),"线下")&IF(F14<>"",F14,IF(OR(E14="—",E14=""),"",E14))&IFERROR(INDEX('费用归属表（快照）'!$F$4:$F$16,MATCH(D14,'费用归属表（快照）'!$A$4:$A$16,0)),"") | Q14: =IF(P14="","",P14-I14) | T14: =IF(D14="","",IFERROR(INDEX('费用归属表（快照）'!$C$4:$C$16,MATCH(D14,'费用归属表（快照）'!$A$4:$A$16,0)),"")) | U14: =IF(D14="","",IF(AND(D14="销售出库费用",B14="深圳星期九"),"永续供应中心 0010401",IF(AND(D14="原料入库费用",E14="小料"),"茶饮小料部 0030902",IFERROR(INDEX('费用归属表（快照）'!$D$4:$D$16,MATCH(D14,'费用归属表（快照）'!$A$4:$A$16,0)),"")))) | V14: =IF(D14="","",IFERROR(INDEX('费用归属表（快照）'!$B$4:$B$16,MATCH(D14,'费用归属表（快照）'!$A$4:$A$16,0)),"")) | W14: =IF(OR(E14="",AND(LEFT(T14,4)<>"6601",LEFT(T14,4)<>"6401")),"",IFERROR(IF(INDEX(选项!$I$2:$I$11,MATCH(E14,选项!$H$2:$H$11,0))="","",INDEX(选项!$I$2:$I$11,MATCH(E14,选项!$H$2:$H$11,0))),"")) | X14: =IF(OR(E14="",AND(LEFT(T14,4)<>"6601",LEFT(T14,4)<>"6401")),"",IFERROR(IF(INDEX(选项!$J$2:$J$11,MATCH(E14,选项!$H$2:$H$11,0))="","",INDEX(选项!$J$2:$J$11,MATCH(E14,选项!$H$2:$H$11,0))),""))
A15: 2026-07 | B15: 深圳星期零 | C15: 跨越物流 | D15: 研发设备采购 | E15: — | G15: 月结 | I15: 329.4 | J15: =IFERROR(INDEX(供应商列表!$F$4:$R$25,MATCH(C15,供应商列表!$A$4:$A$25,0),MATCH(D15,供应商列表!$F$3:$R$3,0)),"") | K15: =IFERROR(ROUND(I15/(1+J15),2),"") | L15: =IFERROR(I15-K15,"") | M15: =IFERROR(INDEX(供应商列表!$B$4:$B$25,MATCH(C15,供应商列表!$A$4:$A$25,0)),"") | N15: ="计提"&M15&(MID(A15,6,2)*1)&"月"&IFERROR(INDEX(供应商列表!$E$4:$E$25,MATCH(C15,供应商列表!$A$4:$A$25,0)),"线下")&IF(F15<>"",F15,IF(OR(E15="—",E15=""),"",E15))&IFERROR(INDEX('费用归属表（快照）'!$F$4:$F$16,MATCH(D15,'费用归属表（快照）'!$A$4:$A$16,0)),"") | Q15: =IF(P15="","",P15-I15) | T15: =IF(D15="","",IFERROR(INDEX('费用归属表（快照）'!$C$4:$C$16,MATCH(D15,'费用归属表（快照）'!$A$4:$A$16,0)),"")) | U15: =IF(D15="","",IF(AND(D15="销售出库费用",B15="深圳星期九"),"永续供应中心 0010401",IF(AND(D15="原料入库费用",E15="小料"),"茶饮小料部 0030902",IFERROR(INDEX('费用归属表（快照）'!$D$4:$D$16,MATCH(D15,'费用归属表（快照）'!$A$4:$A$16,0)),"")))) | V15: =IF(D15="","",IFERROR(INDEX('费用归属表（快照）'!$B$4:$B$16,MATCH(D15,'费用归属表（快照）'!$A$4:$A$16,0)),"")) | W15: =IF(OR(E15="",AND(LEFT(T15,4)<>"6601",LEFT(T15,4)<>"6401")),"",IFERROR(IF(INDEX(选项!$I$2:$I$11,MATCH(E15,选项!$H$2:$H$11,0))="","",INDEX(选项!$I$2:$I$11,MATCH(E15,选项!$H$2:$H$11,0))),"")) | X15: =IF(OR(E15="",AND(LEFT(T15,4)<>"6601",LEFT(T15,4)<>"6401")),"",IFERROR(IF(INDEX(选项!$J$2:$J$11,MATCH(E15,选项!$H$2:$H$11,0))="","",INDEX(选项!$J$2:$J$11,MATCH(E15,选项!$H$2:$H$11,0))),""))
A16: 2026-07 | B16: 深圳星期零 | C16: 跨越物流 | D16: 原料入库费用 | E16: — | F16: 孝感工厂 | G16: 月结 | I16: 991.84 | J16: =IFERROR(INDEX(供应商列表!$F$4:$R$25,MATCH(C16,供应商列表!$A$4:$A$25,0),MATCH(D16,供应商列表!$F$3:$R$3,0)),"") | K16: =IFERROR(ROUND(I16/(1+J16),2),"") | L16: =IFERROR(I16-K16,"") | M16: =IFERROR(INDEX(供应商列表!$B$4:$B$25,MATCH(C16,供应商列表!$A$4:$A$25,0)),"") | N16: ="计提"&M16&(MID(A16,6,2)*1)&"月"&IFERROR(INDEX(供应商列表!$E$4:$E$25,MATCH(C16,供应商列表!$A$4:$A$25,0)),"线下")&IF(F16<>"",F16,IF(OR(E16="—",E16=""),"",E16))&IFERROR(INDEX('费用归属表（快照）'!$F$4:$F$16,MATCH(D16,'费用归属表（快照）'!$A$4:$A$16,0)),"") | Q16: =IF(P16="","",P16-I16) | T16: =IF(D16="","",IFERROR(INDEX('费用归属表（快照）'!$C$4:$C$16,MATCH(D16,'费用归属表（快照）'!$A$4:$A$16,0)),"")) | U16: =IF(D16="","",IF(AND(D16="销售出库费用",B16="深圳星期九"),"永续供应中心 0010401",IF(AND(D16="原料入库费用",E16="小料"),"茶饮小料部 0030902",IFERROR(INDEX('费用归属表（快照）'!$D$4:$D$16,MATCH(D16,'费用归属表（快照）'!$A$4:$A$16,0)),"")))) | V16: =IF(D16="","",IFERROR(INDEX('费用归属表（快照）'!$B$4:$B$16,MATCH(D16,'费用归属表（快照）'!$A$4:$A$16,0)),"")) | W16: =IF(OR(E16="",AND(LEFT(T16,4)<>"6601",LEFT(T16,4)<>"6401")),"",IFERROR(IF(INDEX(选项!$I$2:$I$11,MATCH(E16,选项!$H$2:$H$11,0))="","",INDEX(选项!$I$2:$I$11,MATCH(E16,选项!$H$2:$H$11,0))),"")) | X16: =IF(OR(E16="",AND(LEFT(T16,4)<>"6601",LEFT(T16,4)<>"6401")),"",IFERROR(IF(INDEX(选项!$J$2:$J$11,MATCH(E16,选项!$H$2:$H$11,0))="","",INDEX(选项!$J$2:$J$11,MATCH(E16,选项!$H$2:$H$11,0))),""))
A17: 2026-07 | B17: 深圳星期零 | C17: 跨越物流 | D17: 设备调拨费用 | E17: — | G17: 月结 | I17: 1509.53 | J17: =IFERROR(INDEX(供应商列表!$F$4:$R$25,MATCH(C17,供应商列表!$A$4:$A$25,0),MATCH(D17,供应商列表!$F$3:$R$3,0)),"") | K17: =IFERROR(ROUND(I17/(1+J17),2),"") | L17: =IFERROR(I17-K17,"") | M17: =IFERROR(INDEX(供应商列表!$B$4:$B$25,MATCH(C17,供应商列表!$A$4:$A$25,0)),"") | N17: ="计提"&M17&(MID(A17,6,2)*1)&"月"&IFERROR(INDEX(供应商列表!$E$4:$E$25,MATCH(C17,供应商列表!$A$4:$A$25,0)),"线下")&IF(F17<>"",F17,IF(OR(E17="—",E17=""),"",E17))&IFERROR(INDEX('费用归属表（快照）'!$F$4:$F$16,MATCH(D17,'费用归属表（快照）'!$A$4:$A$16,0)),"") | Q17: =IF(P17="","",P17-I17) | T17: =IF(D17="","",IFERROR(INDEX('费用归属表（快照）'!$C$4:$C$16,MATCH(D17,'费用归属表（快照）'!$A$4:$A$16,0)),"")) | U17: =IF(D17="","",IF(AND(D17="销售出库费用",B17="深圳星期九"),"永续供应中心 0010401",IF(AND(D17="原料入库费用",E17="小料"),"茶饮小料部 0030902",IFERROR(INDEX('费用归属表（快照）'!$D$4:$D$16,MATCH(D17,'费用归属表（快照）'!$A$4:$A$16,0)),"")))) | V17: =IF(D17="","",IFERROR(INDEX('费用归属表（快照）'!$B$4:$B$16,MATCH(D17,'费用归属表（快照）'!$A$4:$A$16,0)),"")) | W17: =IF(OR(E17="",AND(LEFT(T17,4)<>"6601",LEFT(T17,4)<>"6401")),"",IFERROR(IF(INDEX(选项!$I$2:$I$11,MATCH(E17,选项!$H$2:$H$11,0))="","",INDEX(选项!$I$2:$I$11,MATCH(E17,选项!$H$2:$H$11,0))),"")) | X17: =IF(OR(E17="",AND(LEFT(T17,4)<>"6601",LEFT(T17,4)<>"6401")),"",IFERROR(IF(INDEX(选项!$J$2:$J$11,MATCH(E17,选项!$H$2:$H$11,0))="","",INDEX(选项!$J$2:$J$11,MATCH(E17,选项!$H$2:$H$11,0))),""))
A18: 2026-07 | B18: 深圳星期零 | C18: 跨越物流 | D18: 销售出库费用 | E18: 小料 | G18: 月结 | I18: 486.8 | J18: =IFERROR(INDEX(供应商列表!$F$4:$R$25,MATCH(C18,供应商列表!$A$4:$A$25,0),MATCH(D18,供应商列表!$F$3:$R$3,0)),"") | K18: =IFERROR(ROUND(I18/(1+J18),2),"") | L18: =IFERROR(I18-K18,"") | M18: =IFERROR(INDEX(供应商列表!$B$4:$B$25,MATCH(C18,供应商列表!$A$4:$A$25,0)),"") | N18: ="计提"&M18&(MID(A18,6,2)*1)&"月"&IFERROR(INDEX(供应商列表!$E$4:$E$25,MATCH(C18,供应商列表!$A$4:$A$25,0)),"线下")&IF(F18<>"",F18,IF(OR(E18="—",E18=""),"",E18))&IFERROR(INDEX('费用归属表（快照）'!$F$4:$F$16,MATCH(D18,'费用归属表（快照）'!$A$4:$A$16,0)),"") | Q18: =IF(P18="","",P18-I18) | T18: =IF(D18="","",IFERROR(INDEX('费用归属表（快照）'!$C$4:$C$16,MATCH(D18,'费用归属表（快照）'!$A$4:$A$16,0)),"")) | U18: =IF(D18="","",IF(AND(D18="销售出库费用",B18="深圳星期九"),"永续供应中心 0010401",IF(AND(D18="原料入库费用",E18="小料"),"茶饮小料部 0030902",IFERROR(INDEX('费用归属表（快照）'!$D$4:$D$16,MATCH(D18,'费用归属表（快照）'!$A$4:$A$16,0)),"")))) | V18: =IF(D18="","",IFERROR(INDEX('费用归属表（快照）'!$B$4:$B$16,MATCH(D18,'费用归属表（快照）'!$A$4:$A$16,0)),"")) | W18: =IF(OR(E18="",AND(LEFT(T18,4)<>"6601",LEFT(T18,4)<>"6401")),"",IFERROR(IF(INDEX(选项!$I$2:$I$11,MATCH(E18,选项!$H$2:$H$11,0))="","",INDEX(选项!$I$2:$I$11,MATCH(E18,选项!$H$2:$H$11,0))),"")) | X18: =IF(OR(E18="",AND(LEFT(T18,4)<>"6601",LEFT(T18,4)<>"6401")),"",IFERROR(IF(INDEX(选项!$J$2:$J$11,MATCH(E18,选项!$H$2:$H$11,0))="","",INDEX(选项!$J$2:$J$11,MATCH(E18,选项!$H$2:$H$11,0))),""))
A19: 2026-07 | B19: 深圳星期零 | C19: 易风达 | D19: 销售出库费用 | E19: 小料 | G19: 月结 | I19: 400 | J19: =IFERROR(INDEX(供应商列表!$F$4:$R$25,MATCH(C19,供应商列表!$A$4:$A$25,0),MATCH(D19,供应商列表!$F$3:$R$3,0)),"") | K19: =IFERROR(ROUND(I19/(1+J19),2),"") | L19: =IFERROR(I19-K19,"") | M19: =IFERROR(INDEX(供应商列表!$B$4:$B$25,MATCH(C19,供应商列表!$A$4:$A$25,0)),"") | N19: ="计提"&M19&(MID(A19,6,2)*1)&"月"&IFERROR(INDEX(供应商列表!$E$4:$E$25,MATCH(C19,供应商列表!$A$4:$A$25,0)),"线下")&IF(F19<>"",F19,IF(OR(E19="—",E19=""),"",E19))&IFERROR(INDEX('费用归属表（快照）'!$F$4:$F$16,MATCH(D19,'费用归属表（快照）'!$A$4:$A$16,0)),"") | Q19: =IF(P19="","",P19-I19) | T19: =IF(D19="","",IFERROR(INDEX('费用归属表（快照）'!$C$4:$C$16,MATCH(D19,'费用归属表（快照）'!$A$4:$A$16,0)),"")) | U19: =IF(D19="","",IF(AND(D19="销售出库费用",B19="深圳星期九"),"永续供应中心 0010401",IF(AND(D19="原料入库费用",E19="小料"),"茶饮小料部 0030902",IFERROR(INDEX('费用归属表（快照）'!$D$4:$D$16,MATCH(D19,'费用归属表（快照）'!$A$4:$A$16,0)),"")))) | V19: =IF(D19="","",IFERROR(INDEX('费用归属表（快照）'!$B$4:$B$16,MATCH(D19,'费用归属表（快照）'!$A$4:$A$16,0)),"")) | W19: =IF(OR(E19="",AND(LEFT(T19,4)<>"6601",LEFT(T19,4)<>"6401")),"",IFERROR(IF(INDEX(选项!$I$2:$I$11,MATCH(E19,选项!$H$2:$H$11,0))="","",INDEX(选项!$I$2:$I$11,MATCH(E19,选项!$H$2:$H$11,0))),"")) | X19: =IF(OR(E19="",AND(LEFT(T19,4)<>"6601",LEFT(T19,4)<>"6401")),"",IFERROR(IF(INDEX(选项!$J$2:$J$11,MATCH(E19,选项!$H$2:$H$11,0))="","",INDEX(选项!$J$2:$J$11,MATCH(E19,选项!$H$2:$H$11,0))),""))
A20: 2026-07 | B20: 深圳星期零 | C20: 易风达 | D20: 原料入库费用 | E20: 小料 | F20: 小料 | G20: 月结 | I20: 6000 | J20: =IFERROR(INDEX(供应商列表!$F$4:$R$25,MATCH(C20,供应商列表!$A$4:$A$25,0),MATCH(D20,供应商列表!$F$3:$R$3,0)),"") | K20: =IFERROR(ROUND(I20/(1+J20),2),"") | L20: =IFERROR(I20-K20,"") | M20: =IFERROR(INDEX(供应商列表!$B$4:$B$25,MATCH(C20,供应商列表!$A$4:$A$25,0)),"") | N20: ="计提"&M20&(MID(A20,6,2)*1)&"月"&IFERROR(INDEX(供应商列表!$E$4:$E$25,MATCH(C20,供应商列表!$A$4:$A$25,0)),"线下")&IF(F20<>"",F20,IF(OR(E20="—",E20=""),"",E20))&IFERROR(INDEX('费用归属表（快照）'!$F$4:$F$16,MATCH(D20,'费用归属表（快照）'!$A$4:$A$16,0)),"") | Q20: =IF(P20="","",P20-I20) | T20: =IF(D20="","",IFERROR(INDEX('费用归属表（快照）'!$C$4:$C$16,MATCH(D20,'费用归属表（快照）'!$A$4:$A$16,0)),"")) | U20: =IF(D20="","",IF(AND(D20="销售出库费用",B20="深圳星期九"),"永续供应中心 0010401",IF(AND(D20="原料入库费用",E20="小料"),"茶饮小料部 0030902",IFERROR(INDEX('费用归属表（快照）'!$D$4:$D$16,MATCH(D20,'费用归属表（快照）'!$A$4:$A$16,0)),"")))) | V20: =IF(D20="","",IFERROR(INDEX('费用归属表（快照）'!$B$4:$B$16,MATCH(D20,'费用归属表（快照）'!$A$4:$A$16,0)),"")) | W20: =IF(OR(E20="",AND(LEFT(T20,4)<>"6601",LEFT(T20,4)<>"6401")),"",IFERROR(IF(INDEX(选项!$I$2:$I$11,MATCH(E20,选项!$H$2:$H$11,0))="","",INDEX(选项!$I$2:$I$11,MATCH(E20,选项!$H$2:$H$11,0))),"")) | X20: =IF(OR(E20="",AND(LEFT(T20,4)<>"6601",LEFT(T20,4)<>"6401")),"",IFERROR(IF(INDEX(选项!$J$2:$J$11,MATCH(E20,选项!$H$2:$H$11,0))="","",INDEX(选项!$J$2:$J$11,MATCH(E20,选项!$H$2:$H$11,0))),""))
A21: 2026-07 | B21: 深圳星期零 | C21: 易风达 | D21: 成品仓储费用 | E21: — | G21: 月结 | I21: 45281.9 | J21: =IFERROR(INDEX(供应商列表!$F$4:$R$25,MATCH(C21,供应商列表!$A$4:$A$25,0),MATCH(D21,供应商列表!$F$3:$R$3,0)),"") | K21: =IFERROR(ROUND(I21/(1+J21),2),"") | L21: =IFERROR(I21-K21,"") | M21: =IFERROR(INDEX(供应商列表!$B$4:$B$25,MATCH(C21,供应商列表!$A$4:$A$25,0)),"") | N21: ="计提"&M21&(MID(A21,6,2)*1)&"月"&IFERROR(INDEX(供应商列表!$E$4:$E$25,MATCH(C21,供应商列表!$A$4:$A$25,0)),"线下")&IF(F21<>"",F21,IF(OR(E21="—",E21=""),"",E21))&IFERROR(INDEX('费用归属表（快照）'!$F$4:$F$16,MATCH(D21,'费用归属表（快照）'!$A$4:$A$16,0)),"") | Q21: =IF(P21="","",P21-I21) | T21: =IF(D21="","",IFERROR(INDEX('费用归属表（快照）'!$C$4:$C$16,MATCH(D21,'费用归属表（快照）'!$A$4:$A$16,0)),"")) | U21: =IF(D21="","",IF(AND(D21="销售出库费用",B21="深圳星期九"),"永续供应中心 0010401",IF(AND(D21="原料入库费用",E21="小料"),"茶饮小料部 0030902",IFERROR(INDEX('费用归属表（快照）'!$D$4:$D$16,MATCH(D21,'费用归属表（快照）'!$A$4:$A$16,0)),"")))) | V21: =IF(D21="","",IFERROR(INDEX('费用归属表（快照）'!$B$4:$B$16,MATCH(D21,'费用归属表（快照）'!$A$4:$A$16,0)),"")) | W21: =IF(OR(E21="",AND(LEFT(T21,4)<>"6601",LEFT(T21,4)<>"6401")),"",IFERROR(IF(INDEX(选项!$I$2:$I$11,MATCH(E21,选项!$H$2:$H$11,0))="","",INDEX(选项!$I$2:$I$11,MATCH(E21,选项!$H$2:$H$11,0))),"")) | X21: =IF(OR(E21="",AND(LEFT(T21,4)<>"6601",LEFT(T21,4)<>"6401")),"",IFERROR(IF(INDEX(选项!$J$2:$J$11,MATCH(E21,选项!$H$2:$H$11,0))="","",INDEX(选项!$J$2:$J$11,MATCH(E21,选项!$H$2:$H$11,0))),""))
A22: 2026-07 | B22: 深圳星期零 | C22: 诚煜物流 | D22: 销售出库费用 | E22: 鲜食 | G22: 月结 | I22: 183204.47 | J22: =IFERROR(INDEX(供应商列表!$F$4:$R$25,MATCH(C22,供应商列表!$A$4:$A$25,0),MATCH(D22,供应商列表!$F$3:$R$3,0)),"") | K22: =IFERROR(ROUND(I22/(1+J22),2),"") | L22: =IFERROR(I22-K22,"") | M22: =IFERROR(INDEX(供应商列表!$B$4:$B$25,MATCH(C22,供应商列表!$A$4:$A$25,0)),"") | N22: ="计提"&M22&(MID(A22,6,2)*1)&"月"&IFERROR(INDEX(供应商列表!$E$4:$E$25,MATCH(C22,供应商列表!$A$4:$A$25,0)),"线下")&IF(F22<>"",F22,IF(OR(E22="—",E22=""),"",E22))&IFERROR(INDEX('费用归属表（快照）'!$F$4:$F$16,MATCH(D22,'费用归属表（快照）'!$A$4:$A$16,0)),"") | Q22: =IF(P22="","",P22-I22) | T22: =IF(D22="","",IFERROR(INDEX('费用归属表（快照）'!$C$4:$C$16,MATCH(D22,'费用归属表（快照）'!$A$4:$A$16,0)),"")) | U22: =IF(D22="","",IF(AND(D22="销售出库费用",B22="深圳星期九"),"永续供应中心 0010401",IF(AND(D22="原料入库费用",E22="小料"),"茶饮小料部 0030902",IFERROR(INDEX('费用归属表（快照）'!$D$4:$D$16,MATCH(D22,'费用归属表（快照）'!$A$4:$A$16,0)),"")))) | V22: =IF(D22="","",IFERROR(INDEX('费用归属表（快照）'!$B$4:$B$16,MATCH(D22,'费用归属表（快照）'!$A$4:$A$16,0)),"")) | W22: =IF(OR(E22="",AND(LEFT(T22,4)<>"6601",LEFT(T22,4)<>"6401")),"",IFERROR(IF(INDEX(选项!$I$2:$I$11,MATCH(E22,选项!$H$2:$H$11,0))="","",INDEX(选项!$I$2:$I$11,MATCH(E22,选项!$H$2:$H$11,0))),"")) | X22: =IF(OR(E22="",AND(LEFT(T22,4)<>"6601",LEFT(T22,4)<>"6401")),"",IFERROR(IF(INDEX(选项!$J$2:$J$11,MATCH(E22,选项!$H$2:$H$11,0))="","",INDEX(选项!$J$2:$J$11,MATCH(E22,选项!$H$2:$H$11,0))),""))
A23: 2026-07 | B23: 深圳星期零 | C23: 链盟 | D23: 销售出库费用 | E23: 植物肉 | G23: 月结 | I23: 5827.5 | J23: =IFERROR(INDEX(供应商列表!$F$4:$R$25,MATCH(C23,供应商列表!$A$4:$A$25,0),MATCH(D23,供应商列表!$F$3:$R$3,0)),"") | K23: =IFERROR(ROUND(I23/(1+J23),2),"") | L23: =IFERROR(I23-K23,"") | M23: =IFERROR(INDEX(供应商列表!$B$4:$B$25,MATCH(C23,供应商列表!$A$4:$A$25,0)),"") | N23: ="计提"&M23&(MID(A23,6,2)*1)&"月"&IFERROR(INDEX(供应商列表!$E$4:$E$25,MATCH(C23,供应商列表!$A$4:$A$25,0)),"线下")&IF(F23<>"",F23,IF(OR(E23="—",E23=""),"",E23))&IFERROR(INDEX('费用归属表（快照）'!$F$4:$F$16,MATCH(D23,'费用归属表（快照）'!$A$4:$A$16,0)),"") | Q23: =IF(P23="","",P23-I23) | T23: =IF(D23="","",IFERROR(INDEX('费用归属表（快照）'!$C$4:$C$16,MATCH(D23,'费用归属表（快照）'!$A$4:$A$16,0)),"")) | U23: =IF(D23="","",IF(AND(D23="销售出库费用",B23="深圳星期九"),"永续供应中心 0010401",IF(AND(D23="原料入库费用",E23="小料"),"茶饮小料部 0030902",IFERROR(INDEX('费用归属表（快照）'!$D$4:$D$16,MATCH(D23,'费用归属表（快照）'!$A$4:$A$16,0)),"")))) | V23: =IF(D23="","",IFERROR(INDEX('费用归属表（快照）'!$B$4:$B$16,MATCH(D23,'费用归属表（快照）'!$A$4:$A$16,0)),"")) | W23: =IF(OR(E23="",AND(LEFT(T23,4)<>"6601",LEFT(T23,4)<>"6401")),"",IFERROR(IF(INDEX(选项!$I$2:$I$11,MATCH(E23,选项!$H$2:$H$11,0))="","",INDEX(选项!$I$2:$I$11,MATCH(E23,选项!$H$2:$H$11,0))),"")) | X23: =IF(OR(E23="",AND(LEFT(T23,4)<>"6601",LEFT(T23,4)<>"6401")),"",IFERROR(IF(INDEX(选项!$J$2:$J$11,MATCH(E23,选项!$H$2:$H$11,0))="","",INDEX(选项!$J$2:$J$11,MATCH(E23,选项!$H$2:$H$11,0))),""))
A24: 2026-07 | B24: 深圳星期零 | C24: 链盟 | D24: 销售出库费用 | E24: 鲜食 | G24: 月结 | I24: 1500 | J24: =IFERROR(INDEX(供应商列表!$F$4:$R$25,MATCH(C24,供应商列表!$A$4:$A$25,0),MATCH(D24,供应商列表!$F$3:$R$3,0)),"") | K24: =IFERROR(ROUND(I24/(1+J24),2),"") | L24: =IFERROR(I24-K24,"") | M24: =IFERROR(INDEX(供应商列表!$B$4:$B$25,MATCH(C24,供应商列表!$A$4:$A$25,0)),"") | N24: ="计提"&M24&(MID(A24,6,2)*1)&"月"&IFERROR(INDEX(供应商列表!$E$4:$E$25,MATCH(C24,供应商列表!$A$4:$A$25,0)),"线下")&IF(F24<>"",F24,IF(OR(E24="—",E24=""),"",E24))&IFERROR(INDEX('费用归属表（快照）'!$F$4:$F$16,MATCH(D24,'费用归属表（快照）'!$A$4:$A$16,0)),"") | Q24: =IF(P24="","",P24-I24) | T24: =IF(D24="","",IFERROR(INDEX('费用归属表（快照）'!$C$4:$C$16,MATCH(D24,'费用归属表（快照）'!$A$4:$A$16,0)),"")) | U24: =IF(D24="","",IF(AND(D24="销售出库费用",B24="深圳星期九"),"永续供应中心 0010401",IF(AND(D24="原料入库费用",E24="小料"),"茶饮小料部 0030902",IFERROR(INDEX('费用归属表（快照）'!$D$4:$D$16,MATCH(D24,'费用归属表（快照）'!$A$4:$A$16,0)),"")))) | V24: =IF(D24="","",IFERROR(INDEX('费用归属表（快照）'!$B$4:$B$16,MATCH(D24,'费用归属表（快照）'!$A$4:$A$16,0)),"")) | W24: =IF(OR(E24="",AND(LEFT(T24,4)<>"6601",LEFT(T24,4)<>"6401")),"",IFERROR(IF(INDEX(选项!$I$2:$I$11,MATCH(E24,选项!$H$2:$H$11,0))="","",INDEX(选项!$I$2:$I$11,MATCH(E24,选项!$H$2:$H$11,0))),"")) | X24: =IF(OR(E24="",AND(LEFT(T24,4)<>"6601",LEFT(T24,4)<>"6401")),"",IFERROR(IF(INDEX(选项!$J$2:$J$11,MATCH(E24,选项!$H$2:$H$11,0))="","",INDEX(选项!$J$2:$J$11,MATCH(E24,选项!$H$2:$H$11,0))),""))
A25: 2026-07 | B25: 深圳星期零 | C25: 链盟 | D25: 销售出库费用 | E25: 山姆零售 | G25: 月结 | I25: 880 | J25: =IFERROR(INDEX(供应商列表!$F$4:$R$25,MATCH(C25,供应商列表!$A$4:$A$25,0),MATCH(D25,供应商列表!$F$3:$R$3,0)),"") | K25: =IFERROR(ROUND(I25/(1+J25),2),"") | L25: =IFERROR(I25-K25,"") | M25: =IFERROR(INDEX(供应商列表!$B$4:$B$25,MATCH(C25,供应商列表!$A$4:$A$25,0)),"") | N25: ="计提"&M25&(MID(A25,6,2)*1)&"月"&IFERROR(INDEX(供应商列表!$E$4:$E$25,MATCH(C25,供应商列表!$A$4:$A$25,0)),"线下")&IF(F25<>"",F25,IF(OR(E25="—",E25=""),"",E25))&IFERROR(INDEX('费用归属表（快照）'!$F$4:$F$16,MATCH(D25,'费用归属表（快照）'!$A$4:$A$16,0)),"") | Q25: =IF(P25="","",P25-I25) | T25: =IF(D25="","",IFERROR(INDEX('费用归属表（快照）'!$C$4:$C$16,MATCH(D25,'费用归属表（快照）'!$A$4:$A$16,0)),"")) | U25: =IF(D25="","",IF(AND(D25="销售出库费用",B25="深圳星期九"),"永续供应中心 0010401",IF(AND(D25="原料入库费用",E25="小料"),"茶饮小料部 0030902",IFERROR(INDEX('费用归属表（快照）'!$D$4:$D$16,MATCH(D25,'费用归属表（快照）'!$A$4:$A$16,0)),"")))) | V25: =IF(D25="","",IFERROR(INDEX('费用归属表（快照）'!$B$4:$B$16,MATCH(D25,'费用归属表（快照）'!$A$4:$A$16,0)),"")) | W25: =IF(OR(E25="",AND(LEFT(T25,4)<>"6601",LEFT(T25,4)<>"6401")),"",IFERROR(IF(INDEX(选项!$I$2:$I$11,MATCH(E25,选项!$H$2:$H$11,0))="","",INDEX(选项!$I$2:$I$11,MATCH(E25,选项!$H$2:$H$11,0))),"")) | X25: =IF(OR(E25="",AND(LEFT(T25,4)<>"6601",LEFT(T25,4)<>"6401")),"",IFERROR(IF(INDEX(选项!$J$2:$J$11,MATCH(E25,选项!$H$2:$H$11,0))="","",INDEX(选项!$J$2:$J$11,MATCH(E25,选项!$H$2:$H$11,0))),""))
A26: 2026-07 | B26: 深圳星期零 | C26: 链盟 | D26: 销售出库费用 | E26: 零售 | G26: 月结 | I26: 3350 | J26: =IFERROR(INDEX(供应商列表!$F$4:$R$25,MATCH(C26,供应商列表!$A$4:$A$25,0),MATCH(D26,供应商列表!$F$3:$R$3,0)),"") | K26: =IFERROR(ROUND(I26/(1+J26),2),"") | L26: =IFERROR(I26-K26,"") | M26: =IFERROR(INDEX(供应商列表!$B$4:$B$25,MATCH(C26,供应商列表!$A$4:$A$25,0)),"") | N26: ="计提"&M26&(MID(A26,6,2)*1)&"月"&IFERROR(INDEX(供应商列表!$E$4:$E$25,MATCH(C26,供应商列表!$A$4:$A$25,0)),"线下")&IF(F26<>"",F26,IF(OR(E26="—",E26=""),"",E26))&IFERROR(INDEX('费用归属表（快照）'!$F$4:$F$16,MATCH(D26,'费用归属表（快照）'!$A$4:$A$16,0)),"") | Q26: =IF(P26="","",P26-I26) | T26: =IF(D26="","",IFERROR(INDEX('费用归属表（快照）'!$C$4:$C$16,MATCH(D26,'费用归属表（快照）'!$A$4:$A$16,0)),"")) | U26: =IF(D26="","",IF(AND(D26="销售出库费用",B26="深圳星期九"),"永续供应中心 0010401",IF(AND(D26="原料入库费用",E26="小料"),"茶饮小料部 0030902",IFERROR(INDEX('费用归属表（快照）'!$D$4:$D$16,MATCH(D26,'费用归属表（快照）'!$A$4:$A$16,0)),"")))) | V26: =IF(D26="","",IFERROR(INDEX('费用归属表（快照）'!$B$4:$B$16,MATCH(D26,'费用归属表（快照）'!$A$4:$A$16,0)),"")) | W26: =IF(OR(E26="",AND(LEFT(T26,4)<>"6601",LEFT(T26,4)<>"6401")),"",IFERROR(IF(INDEX(选项!$I$2:$I$11,MATCH(E26,选项!$H$2:$H$11,0))="","",INDEX(选项!$I$2:$I$11,MATCH(E26,选项!$H$2:$H$11,0))),"")) | X26: =IF(OR(E26="",AND(LEFT(T26,4)<>"6601",LEFT(T26,4)<>"6401")),"",IFERROR(IF(INDEX(选项!$J$2:$J$11,MATCH(E26,选项!$H$2:$H$11,0))="","",INDEX(选项!$J$2:$J$11,MATCH(E26,选项!$H$2:$H$11,0))),""))
A27: 2026-07 | B27: 深圳星期零 | C27: 链盟 | D27: 销售出库费用 | E27: 小料 | G27: 月结 | I27: 15760 | J27: =IFERROR(INDEX(供应商列表!$F$4:$R$25,MATCH(C27,供应商列表!$A$4:$A$25,0),MATCH(D27,供应商列表!$F$3:$R$3,0)),"") | K27: =IFERROR(ROUND(I27/(1+J27),2),"") | L27: =IFERROR(I27-K27,"") | M27: =IFERROR(INDEX(供应商列表!$B$4:$B$25,MATCH(C27,供应商列表!$A$4:$A$25,0)),"") | N27: ="计提"&M27&(MID(A27,6,2)*1)&"月"&IFERROR(INDEX(供应商列表!$E$4:$E$25,MATCH(C27,供应商列表!$A$4:$A$25,0)),"线下")&IF(F27<>"",F27,IF(OR(E27="—",E27=""),"",E27))&IFERROR(INDEX('费用归属表（快照）'!$F$4:$F$16,MATCH(D27,'费用归属表（快照）'!$A$4:$A$16,0)),"") | Q27: =IF(P27="","",P27-I27) | T27: =IF(D27="","",IFERROR(INDEX('费用归属表（快照）'!$C$4:$C$16,MATCH(D27,'费用归属表（快照）'!$A$4:$A$16,0)),"")) | U27: =IF(D27="","",IF(AND(D27="销售出库费用",B27="深圳星期九"),"永续供应中心 0010401",IF(AND(D27="原料入库费用",E27="小料"),"茶饮小料部 0030902",IFERROR(INDEX('费用归属表（快照）'!$D$4:$D$16,MATCH(D27,'费用归属表（快照）'!$A$4:$A$16,0)),"")))) | V27: =IF(D27="","",IFERROR(INDEX('费用归属表（快照）'!$B$4:$B$16,MATCH(D27,'费用归属表（快照）'!$A$4:$A$16,0)),"")) | W27: =IF(OR(E27="",AND(LEFT(T27,4)<>"6601",LEFT(T27,4)<>"6401")),"",IFERROR(IF(INDEX(选项!$I$2:$I$11,MATCH(E27,选项!$H$2:$H$11,0))="","",INDEX(选项!$I$2:$I$11,MATCH(E27,选项!$H$2:$H$11,0))),"")) | X27: =IF(OR(E27="",AND(LEFT(T27,4)<>"6601",LEFT(T27,4)<>"6401")),"",IFERROR(IF(INDEX(选项!$J$2:$J$11,MATCH(E27,选项!$H$2:$H$11,0))="","",INDEX(选项!$J$2:$J$11,MATCH(E27,选项!$H$2:$H$11,0))),""))
A28: 2026-07 | B28: 深圳星期零 | C28: 链盟 | D28: 原料入库费用 | E28: — | F28: 孝感工厂 | G28: 月结 | I28: 760 | J28: =IFERROR(INDEX(供应商列表!$F$4:$R$25,MATCH(C28,供应商列表!$A$4:$A$25,0),MATCH(D28,供应商列表!$F$3:$R$3,0)),"") | K28: =IFERROR(ROUND(I28/(1+J28),2),"") | L28: =IFERROR(I28-K28,"") | M28: =IFERROR(INDEX(供应商列表!$B$4:$B$25,MATCH(C28,供应商列表!$A$4:$A$25,0)),"") | N28: ="计提"&M28&(MID(A28,6,2)*1)&"月"&IFERROR(INDEX(供应商列表!$E$4:$E$25,MATCH(C28,供应商列表!$A$4:$A$25,0)),"线下")&IF(F28<>"",F28,IF(OR(E28="—",E28=""),"",E28))&IFERROR(INDEX('费用归属表（快照）'!$F$4:$F$16,MATCH(D28,'费用归属表（快照）'!$A$4:$A$16,0)),"") | Q28: =IF(P28="","",P28-I28) | T28: =IF(D28="","",IFERROR(INDEX('费用归属表（快照）'!$C$4:$C$16,MATCH(D28,'费用归属表（快照）'!$A$4:$A$16,0)),"")) | U28: =IF(D28="","",IF(AND(D28="销售出库费用",B28="深圳星期九"),"永续供应中心 0010401",IF(AND(D28="原料入库费用",E28="小料"),"茶饮小料部 0030902",IFERROR(INDEX('费用归属表（快照）'!$D$4:$D$16,MATCH(D28,'费用归属表（快照）'!$A$4:$A$16,0)),"")))) | V28: =IF(D28="","",IFERROR(INDEX('费用归属表（快照）'!$B$4:$B$16,MATCH(D28,'费用归属表（快照）'!$A$4:$A$16,0)),"")) | W28: =IF(OR(E28="",AND(LEFT(T28,4)<>"6601",LEFT(T28,4)<>"6401")),"",IFERROR(IF(INDEX(选项!$I$2:$I$11,MATCH(E28,选项!$H$2:$H$11,0))="","",INDEX(选项!$I$2:$I$11,MATCH(E28,选项!$H$2:$H$11,0))),"")) | X28: =IF(OR(E28="",AND(LEFT(T28,4)<>"6601",LEFT(T28,4)<>"6401")),"",IFERROR(IF(INDEX(选项!$J$2:$J$11,MATCH(E28,选项!$H$2:$H$11,0))="","",INDEX(选项!$J$2:$J$11,MATCH(E28,选项!$H$2:$H$11,0))),""))
A29: 2026-07 | B29: 深圳星期零 | C29: 链盟 | D29: 原料入库费用 | E29: 小料 | F29: 小料 | G29: 月结 | I29: 24600 | J29: =IFERROR(INDEX(供应商列表!$F$4:$R$25,MATCH(C29,供应商列表!$A$4:$A$25,0),MATCH(D29,供应商列表!$F$3:$R$3,0)),"") | K29: =IFERROR(ROUND(I29/(1+J29),2),"") | L29: =IFERROR(I29-K29,"") | M29: =IFERROR(INDEX(供应商列表!$B$4:$B$25,MATCH(C29,供应商列表!$A$4:$A$25,0)),"") | N29: ="计提"&M29&(MID(A29,6,2)*1)&"月"&IFERROR(INDEX(供应商列表!$E$4:$E$25,MATCH(C29,供应商列表!$A$4:$A$25,0)),"线下")&IF(F29<>"",F29,IF(OR(E29="—",E29=""),"",E29))&IFERROR(INDEX('费用归属表（快照）'!$F$4:$F$16,MATCH(D29,'费用归属表（快照）'!$A$4:$A$16,0)),"") | Q29: =IF(P29="","",P29-I29) | T29: =IF(D29="","",IFERROR(INDEX('费用归属表（快照）'!$C$4:$C$16,MATCH(D29,'费用归属表（快照）'!$A$4:$A$16,0)),"")) | U29: =IF(D29="","",IF(AND(D29="销售出库费用",B29="深圳星期九"),"永续供应中心 0010401",IF(AND(D29="原料入库费用",E29="小料"),"茶饮小料部 0030902",IFERROR(INDEX('费用归属表（快照）'!$D$4:$D$16,MATCH(D29,'费用归属表（快照）'!$A$4:$A$16,0)),"")))) | V29: =IF(D29="","",IFERROR(INDEX('费用归属表（快照）'!$B$4:$B$16,MATCH(D29,'费用归属表（快照）'!$A$4:$A$16,0)),"")) | W29: =IF(OR(E29="",AND(LEFT(T29,4)<>"6601",LEFT(T29,4)<>"6401")),"",IFERROR(IF(INDEX(选项!$I$2:$I$11,MATCH(E29,选项!$H$2:$H$11,0))="","",INDEX(选项!$I$2:$I$11,MATCH(E29,选项!$H$2:$H$11,0))),"")) | X29: =IF(OR(E29="",AND(LEFT(T29,4)<>"6601",LEFT(T29,4)<>"6401")),"",IFERROR(IF(INDEX(选项!$J$2:$J$11,MATCH(E29,选项!$H$2:$H$11,0))="","",INDEX(选项!$J$2:$J$11,MATCH(E29,选项!$H$2:$H$11,0))),""))
A30: 2026-07 | B30: 深圳星期零 | C30: 链盟 | D30: 销售出库费用 | E30: 小料 | G30: 月结 | I30: 1407.5 | J30: =IFERROR(INDEX(供应商列表!$F$4:$R$25,MATCH(C30,供应商列表!$A$4:$A$25,0),MATCH(D30,供应商列表!$F$3:$R$3,0)),"") | K30: =IFERROR(ROUND(I30/(1+J30),2),"") | L30: =IFERROR(I30-K30,"") | M30: =IFERROR(INDEX(供应商列表!$B$4:$B$25,MATCH(C30,供应商列表!$A$4:$A$25,0)),"") | N30: ="计提"&M30&(MID(A30,6,2)*1)&"月"&IFERROR(INDEX(供应商列表!$E$4:$E$25,MATCH(C30,供应商列表!$A$4:$A$25,0)),"线下")&IF(F30<>"",F30,IF(OR(E30="—",E30=""),"",E30))&IFERROR(INDEX('费用归属表（快照）'!$F$4:$F$16,MATCH(D30,'费用归属表（快照）'!$A$4:$A$16,0)),"") | Q30: =IF(P30="","",P30-I30) | T30: =IF(D30="","",IFERROR(INDEX('费用归属表（快照）'!$C$4:$C$16,MATCH(D30,'费用归属表（快照）'!$A$4:$A$16,0)),"")) | U30: =IF(D30="","",IF(AND(D30="销售出库费用",B30="深圳星期九"),"永续供应中心 0010401",IF(AND(D30="原料入库费用",E30="小料"),"茶饮小料部 0030902",IFERROR(INDEX('费用归属表（快照）'!$D$4:$D$16,MATCH(D30,'费用归属表（快照）'!$A$4:$A$16,0)),"")))) | V30: =IF(D30="","",IFERROR(INDEX('费用归属表（快照）'!$B$4:$B$16,MATCH(D30,'费用归属表（快照）'!$A$4:$A$16,0)),"")) | W30: =IF(OR(E30="",AND(LEFT(T30,4)<>"6601",LEFT(T30,4)<>"6401")),"",IFERROR(IF(INDEX(选项!$I$2:$I$11,MATCH(E30,选项!$H$2:$H$11,0))="","",INDEX(选项!$I$2:$I$11,MATCH(E30,选项!$H$2:$H$11,0))),"")) | X30: =IF(OR(E30="",AND(LEFT(T30,4)<>"6601",LEFT(T30,4)<>"6401")),"",IFERROR(IF(INDEX(选项!$J$2:$J$11,MATCH(E30,选项!$H$2:$H$11,0))="","",INDEX(选项!$J$2:$J$11,MATCH(E30,选项!$H$2:$H$11,0))),""))
A31: 2026-07 | B31: 深圳星期零 | C31: 路凯（13%） | D31: 销售出库费用 | E31: 山姆零售 | G31: 月结 | I31: 3265.31 | J31: =IFERROR(INDEX(供应商列表!$F$4:$R$25,MATCH(C31,供应商列表!$A$4:$A$25,0),MATCH(D31,供应商列表!$F$3:$R$3,0)),"") | K31: =IFERROR(ROUND(I31/(1+J31),2),"") | L31: =IFERROR(I31-K31,"") | M31: =IFERROR(INDEX(供应商列表!$B$4:$B$25,MATCH(C31,供应商列表!$A$4:$A$25,0)),"") | N31: ="计提"&M31&(MID(A31,6,2)*1)&"月"&IFERROR(INDEX(供应商列表!$E$4:$E$25,MATCH(C31,供应商列表!$A$4:$A$25,0)),"线下")&IF(F31<>"",F31,IF(OR(E31="—",E31=""),"",E31))&IFERROR(INDEX('费用归属表（快照）'!$F$4:$F$16,MATCH(D31,'费用归属表（快照）'!$A$4:$A$16,0)),"") | Q31: =IF(P31="","",P31-I31) | T31: =IF(D31="","",IFERROR(INDEX('费用归属表（快照）'!$C$4:$C$16,MATCH(D31,'费用归属表（快照）'!$A$4:$A$16,0)),"")) | U31: =IF(D31="","",IF(AND(D31="销售出库费用",B31="深圳星期九"),"永续供应中心 0010401",IF(AND(D31="原料入库费用",E31="小料"),"茶饮小料部 0030902",IFERROR(INDEX('费用归属表（快照）'!$D$4:$D$16,MATCH(D31,'费用归属表（快照）'!$A$4:$A$16,0)),"")))) | V31: =IF(D31="","",IFERROR(INDEX('费用归属表（快照）'!$B$4:$B$16,MATCH(D31,'费用归属表（快照）'!$A$4:$A$16,0)),"")) | W31: =IF(OR(E31="",AND(LEFT(T31,4)<>"6601",LEFT(T31,4)<>"6401")),"",IFERROR(IF(INDEX(选项!$I$2:$I$11,MATCH(E31,选项!$H$2:$H$11,0))="","",INDEX(选项!$I$2:$I$11,MATCH(E31,选项!$H$2:$H$11,0))),"")) | X31: =IF(OR(E31="",AND(LEFT(T31,4)<>"6601",LEFT(T31,4)<>"6401")),"",IFERROR(IF(INDEX(选项!$J$2:$J$11,MATCH(E31,选项!$H$2:$H$11,0))="","",INDEX(选项!$J$2:$J$11,MATCH(E31,选项!$H$2:$H$11,0))),""))
A32: 2026-07 | B32: 深圳星期零 | C32: 中通快运 | D32: 销售出库费用 | E32: 植物肉 | G32: 月结 | I32: 208.6 | J32: =IFERROR(INDEX(供应商列表!$F$4:$R$25,MATCH(C32,供应商列表!$A$4:$A$25,0),MATCH(D32,供应商列表!$F$3:$R$3,0)),"") | K32: =IFERROR(ROUND(I32/(1+J32),2),"") | L32: =IFERROR(I32-K32,"") | M32: =IFERROR(INDEX(供应商列表!$B$4:$B$25,MATCH(C32,供应商列表!$A$4:$A$25,0)),"") | N32: ="计提"&M32&(MID(A32,6,2)*1)&"月"&IFERROR(INDEX(供应商列表!$E$4:$E$25,MATCH(C32,供应商列表!$A$4:$A$25,0)),"线下")&IF(F32<>"",F32,IF(OR(E32="—",E32=""),"",E32))&IFERROR(INDEX('费用归属表（快照）'!$F$4:$F$16,MATCH(D32,'费用归属表（快照）'!$A$4:$A$16,0)),"") | Q32: =IF(P32="","",P32-I32) | T32: =IF(D32="","",IFERROR(INDEX('费用归属表（快照）'!$C$4:$C$16,MATCH(D32,'费用归属表（快照）'!$A$4:$A$16,0)),"")) | U32: =IF(D32="","",IF(AND(D32="销售出库费用",B32="深圳星期九"),"永续供应中心 0010401",IF(AND(D32="原料入库费用",E32="小料"),"茶饮小料部 0030902",IFERROR(INDEX('费用归属表（快照）'!$D$4:$D$16,MATCH(D32,'费用归属表（快照）'!$A$4:$A$16,0)),"")))) | V32: =IF(D32="","",IFERROR(INDEX('费用归属表（快照）'!$B$4:$B$16,MATCH(D32,'费用归属表（快照）'!$A$4:$A$16,0)),"")) | W32: =IF(OR(E32="",AND(LEFT(T32,4)<>"6601",LEFT(T32,4)<>"6401")),"",IFERROR(IF(INDEX(选项!$I$2:$I$11,MATCH(E32,选项!$H$2:$H$11,0))="","",INDEX(选项!$I$2:$I$11,MATCH(E32,选项!$H$2:$H$11,0))),"")) | X32: =IF(OR(E32="",AND(LEFT(T32,4)<>"6601",LEFT(T32,4)<>"6401")),"",IFERROR(IF(INDEX(选项!$J$2:$J$11,MATCH(E32,选项!$H$2:$H$11,0))="","",INDEX(选项!$J$2:$J$11,MATCH(E32,选项!$H$2:$H$11,0))),""))
A33: 2026-07 | B33: 深圳星期零 | C33: 中通快运 | D33: 销售出库费用 | E33: 山姆零售 | G33: 月结 | I33: 26.25 | J33: =IFERROR(INDEX(供应商列表!$F$4:$R$25,MATCH(C33,供应商列表!$A$4:$A$25,0),MATCH(D33,供应商列表!$F$3:$R$3,0)),"") | K33: =IFERROR(ROUND(I33/(1+J33),2),"") | L33: =IFERROR(I33-K33,"") | M33: =IFERROR(INDEX(供应商列表!$B$4:$B$25,MATCH(C33,供应商列表!$A$4:$A$25,0)),"") | N33: ="计提"&M33&(MID(A33,6,2)*1)&"月"&IFERROR(INDEX(供应商列表!$E$4:$E$25,MATCH(C33,供应商列表!$A$4:$A$25,0)),"线下")&IF(F33<>"",F33,IF(OR(E33="—",E33=""),"",E33))&IFERROR(INDEX('费用归属表（快照）'!$F$4:$F$16,MATCH(D33,'费用归属表（快照）'!$A$4:$A$16,0)),"") | Q33: =IF(P33="","",P33-I33) | T33: =IF(D33="","",IFERROR(INDEX('费用归属表（快照）'!$C$4:$C$16,MATCH(D33,'费用归属表（快照）'!$A$4:$A$16,0)),"")) | U33: =IF(D33="","",IF(AND(D33="销售出库费用",B33="深圳星期九"),"永续供应中心 0010401",IF(AND(D33="原料入库费用",E33="小料"),"茶饮小料部 0030902",IFERROR(INDEX('费用归属表（快照）'!$D$4:$D$16,MATCH(D33,'费用归属表（快照）'!$A$4:$A$16,0)),"")))) | V33: =IF(D33="","",IFERROR(INDEX('费用归属表（快照）'!$B$4:$B$16,MATCH(D33,'费用归属表（快照）'!$A$4:$A$16,0)),"")) | W33: =IF(OR(E33="",AND(LEFT(T33,4)<>"6601",LEFT(T33,4)<>"6401")),"",IFERROR(IF(INDEX(选项!$I$2:$I$11,MATCH(E33,选项!$H$2:$H$11,0))="","",INDEX(选项!$I$2:$I$11,MATCH(E33,选项!$H$2:$H$11,0))),"")) | X33: =IF(OR(E33="",AND(LEFT(T33,4)<>"6601",LEFT(T33,4)<>"6401")),"",IFERROR(IF(INDEX(选项!$J$2:$J$11,MATCH(E33,选项!$H$2:$H$11,0))="","",INDEX(选项!$J$2:$J$11,MATCH(E33,选项!$H$2:$H$11,0))),""))
A34: 2026-07 | B34: 深圳星期零 | C34: 中通快运 | D34: 销售出库费用 | E34: 零售 | G34: 月结 | I34: 21 | J34: =IFERROR(INDEX(供应商列表!$F$4:$R$25,MATCH(C34,供应商列表!$A$4:$A$25,0),MATCH(D34,供应商列表!$F$3:$R$3,0)),"") | K34: =IFERROR(ROUND(I34/(1+J34),2),"") | L34: =IFERROR(I34-K34,"") | M34: =IFERROR(INDEX(供应商列表!$B$4:$B$25,MATCH(C34,供应商列表!$A$4:$A$25,0)),"") | N34: ="计提"&M34&(MID(A34,6,2)*1)&"月"&IFERROR(INDEX(供应商列表!$E$4:$E$25,MATCH(C34,供应商列表!$A$4:$A$25,0)),"线下")&IF(F34<>"",F34,IF(OR(E34="—",E34=""),"",E34))&IFERROR(INDEX('费用归属表（快照）'!$F$4:$F$16,MATCH(D34,'费用归属表（快照）'!$A$4:$A$16,0)),"") | Q34: =IF(P34="","",P34-I34) | T34: =IF(D34="","",IFERROR(INDEX('费用归属表（快照）'!$C$4:$C$16,MATCH(D34,'费用归属表（快照）'!$A$4:$A$16,0)),"")) | U34: =IF(D34="","",IF(AND(D34="销售出库费用",B34="深圳星期九"),"永续供应中心 0010401",IF(AND(D34="原料入库费用",E34="小料"),"茶饮小料部 0030902",IFERROR(INDEX('费用归属表（快照）'!$D$4:$D$16,MATCH(D34,'费用归属表（快照）'!$A$4:$A$16,0)),"")))) | V34: =IF(D34="","",IFERROR(INDEX('费用归属表（快照）'!$B$4:$B$16,MATCH(D34,'费用归属表（快照）'!$A$4:$A$16,0)),"")) | W34: =IF(OR(E34="",AND(LEFT(T34,4)<>"6601",LEFT(T34,4)<>"6401")),"",IFERROR(IF(INDEX(选项!$I$2:$I$11,MATCH(E34,选项!$H$2:$H$11,0))="","",INDEX(选项!$I$2:$I$11,MATCH(E34,选项!$H$2:$H$11,0))),"")) | X34: =IF(OR(E34="",AND(LEFT(T34,4)<>"6601",LEFT(T34,4)<>"6401")),"",IFERROR(IF(INDEX(选项!$J$2:$J$11,MATCH(E34,选项!$H$2:$H$11,0))="","",INDEX(选项!$J$2:$J$11,MATCH(E34,选项!$H$2:$H$11,0))),""))
A35: 2026-07 | B35: 深圳星期零 | C35: 中通快运 | D35: 研发设备采购 | E35: — | G35: 月结 | I35: 207.1 | J35: =IFERROR(INDEX(供应商列表!$F$4:$R$25,MATCH(C35,供应商列表!$A$4:$A$25,0),MATCH(D35,供应商列表!$F$3:$R$3,0)),"") | K35: =IFERROR(ROUND(I35/(1+J35),2),"") | L35: =IFERROR(I35-K35,"") | M35: =IFERROR(INDEX(供应商列表!$B$4:$B$25,MATCH(C35,供应商列表!$A$4:$A$25,0)),"") | N35: ="计提"&M35&(MID(A35,6,2)*1)&"月"&IFERROR(INDEX(供应商列表!$E$4:$E$25,MATCH(C35,供应商列表!$A$4:$A$25,0)),"线下")&IF(F35<>"",F35,IF(OR(E35="—",E35=""),"",E35))&IFERROR(INDEX('费用归属表（快照）'!$F$4:$F$16,MATCH(D35,'费用归属表（快照）'!$A$4:$A$16,0)),"") | Q35: =IF(P35="","",P35-I35) | T35: =IF(D35="","",IFERROR(INDEX('费用归属表（快照）'!$C$4:$C$16,MATCH(D35,'费用归属表（快照）'!$A$4:$A$16,0)),"")) | U35: =IF(D35="","",IF(AND(D35="销售出库费用",B35="深圳星期九"),"永续供应中心 0010401",IF(AND(D35="原料入库费用",E35="小料"),"茶饮小料部 0030902",IFERROR(INDEX('费用归属表（快照）'!$D$4:$D$16,MATCH(D35,'费用归属表（快照）'!$A$4:$A$16,0)),"")))) | V35: =IF(D35="","",IFERROR(INDEX('费用归属表（快照）'!$B$4:$B$16,MATCH(D35,'费用归属表（快照）'!$A$4:$A$16,0)),"")) | W35: =IF(OR(E35="",AND(LEFT(T35,4)<>"6601",LEFT(T35,4)<>"6401")),"",IFERROR(IF(INDEX(选项!$I$2:$I$11,MATCH(E35,选项!$H$2:$H$11,0))="","",INDEX(选项!$I$2:$I$11,MATCH(E35,选项!$H$2:$H$11,0))),"")) | X35: =IF(OR(E35="",AND(LEFT(T35,4)<>"6601",LEFT(T35,4)<>"6401")),"",IFERROR(IF(INDEX(选项!$J$2:$J$11,MATCH(E35,选项!$H$2:$H$11,0))="","",INDEX(选项!$J$2:$J$11,MATCH(E35,选项!$H$2:$H$11,0))),""))
A36: 2026-07 | B36: 深圳星期零 | C36: 极鲜达 | D36: 销售出库费用 | E36: 植物肉 | G36: 月结 | I36: 13607.96 | J36: =IFERROR(INDEX(供应商列表!$F$4:$R$25,MATCH(C36,供应商列表!$A$4:$A$25,0),MATCH(D36,供应商列表!$F$3:$R$3,0)),"") | K36: =IFERROR(ROUND(I36/(1+J36),2),"") | L36: =IFERROR(I36-K36,"") | M36: =IFERROR(INDEX(供应商列表!$B$4:$B$25,MATCH(C36,供应商列表!$A$4:$A$25,0)),"") | N36: ="计提"&M36&(MID(A36,6,2)*1)&"月"&IFERROR(INDEX(供应商列表!$E$4:$E$25,MATCH(C36,供应商列表!$A$4:$A$25,0)),"线下")&IF(F36<>"",F36,IF(OR(E36="—",E36=""),"",E36))&IFERROR(INDEX('费用归属表（快照）'!$F$4:$F$16,MATCH(D36,'费用归属表（快照）'!$A$4:$A$16,0)),"") | Q36: =IF(P36="","",P36-I36) | T36: =IF(D36="","",IFERROR(INDEX('费用归属表（快照）'!$C$4:$C$16,MATCH(D36,'费用归属表（快照）'!$A$4:$A$16,0)),"")) | U36: =IF(D36="","",IF(AND(D36="销售出库费用",B36="深圳星期九"),"永续供应中心 0010401",IF(AND(D36="原料入库费用",E36="小料"),"茶饮小料部 0030902",IFERROR(INDEX('费用归属表（快照）'!$D$4:$D$16,MATCH(D36,'费用归属表（快照）'!$A$4:$A$16,0)),"")))) | V36: =IF(D36="","",IFERROR(INDEX('费用归属表（快照）'!$B$4:$B$16,MATCH(D36,'费用归属表（快照）'!$A$4:$A$16,0)),"")) | W36: =IF(OR(E36="",AND(LEFT(T36,4)<>"6601",LEFT(T36,4)<>"6401")),"",IFERROR(IF(INDEX(选项!$I$2:$I$11,MATCH(E36,选项!$H$2:$H$11,0))="","",INDEX(选项!$I$2:$I$11,MATCH(E36,选项!$H$2:$H$11,0))),"")) | X36: =IF(OR(E36="",AND(LEFT(T36,4)<>"6601",LEFT(T36,4)<>"6401")),"",IFERROR(IF(INDEX(选项!$J$2:$J$11,MATCH(E36,选项!$H$2:$H$11,0))="","",INDEX(选项!$J$2:$J$11,MATCH(E36,选项!$H$2:$H$11,0))),""))
A37: 2026-07 | B37: 深圳星期零 | C37: 极鲜达 | D37: 销售出库费用 | E37: 山姆零售 | G37: 月结 | I37: 118762.7 | J37: =IFERROR(INDEX(供应商列表!$F$4:$R$25,MATCH(C37,供应商列表!$A$4:$A$25,0),MATCH(D37,供应商列表!$F$3:$R$3,0)),"") | K37: =IFERROR(ROUND(I37/(1+J37),2),"") | L37: =IFERROR(I37-K37,"") | M37: =IFERROR(INDEX(供应商列表!$B$4:$B$25,MATCH(C37,供应商列表!$A$4:$A$25,0)),"") | N37: ="计提"&M37&(MID(A37,6,2)*1)&"月"&IFERROR(INDEX(供应商列表!$E$4:$E$25,MATCH(C37,供应商列表!$A$4:$A$25,0)),"线下")&IF(F37<>"",F37,IF(OR(E37="—",E37=""),"",E37))&IFERROR(INDEX('费用归属表（快照）'!$F$4:$F$16,MATCH(D37,'费用归属表（快照）'!$A$4:$A$16,0)),"") | Q37: =IF(P37="","",P37-I37) | T37: =IF(D37="","",IFERROR(INDEX('费用归属表（快照）'!$C$4:$C$16,MATCH(D37,'费用归属表（快照）'!$A$4:$A$16,0)),"")) | U37: =IF(D37="","",IF(AND(D37="销售出库费用",B37="深圳星期九"),"永续供应中心 0010401",IF(AND(D37="原料入库费用",E37="小料"),"茶饮小料部 0030902",IFERROR(INDEX('费用归属表（快照）'!$D$4:$D$16,MATCH(D37,'费用归属表（快照）'!$A$4:$A$16,0)),"")))) | V37: =IF(D37="","",IFERROR(INDEX('费用归属表（快照）'!$B$4:$B$16,MATCH(D37,'费用归属表（快照）'!$A$4:$A$16,0)),"")) | W37: =IF(OR(E37="",AND(LEFT(T37,4)<>"6601",LEFT(T37,4)<>"6401")),"",IFERROR(IF(INDEX(选项!$I$2:$I$11,MATCH(E37,选项!$H$2:$H$11,0))="","",INDEX(选项!$I$2:$I$11,MATCH(E37,选项!$H$2:$H$11,0))),"")) | X37: =IF(OR(E37="",AND(LEFT(T37,4)<>"6601",LEFT(T37,4)<>"6401")),"",IFERROR(IF(INDEX(选项!$J$2:$J$11,MATCH(E37,选项!$H$2:$H$11,0))="","",INDEX(选项!$J$2:$J$11,MATCH(E37,选项!$H$2:$H$11,0))),""))
A38: 2026-07 | B38: 深圳星期零 | C38: 极鲜达 | D38: 销售出库费用 | E38: 豆蛋制品 | G38: 月结 | I38: 12814.27 | J38: =IFERROR(INDEX(供应商列表!$F$4:$R$25,MATCH(C38,供应商列表!$A$4:$A$25,0),MATCH(D38,供应商列表!$F$3:$R$3,0)),"") | K38: =IFERROR(ROUND(I38/(1+J38),2),"") | L38: =IFERROR(I38-K38,"") | M38: =IFERROR(INDEX(供应商列表!$B$4:$B$25,MATCH(C38,供应商列表!$A$4:$A$25,0)),"") | N38: ="计提"&M38&(MID(A38,6,2)*1)&"月"&IFERROR(INDEX(供应商列表!$E$4:$E$25,MATCH(C38,供应商列表!$A$4:$A$25,0)),"线下")&IF(F38<>"",F38,IF(OR(E38="—",E38=""),"",E38))&IFERROR(INDEX('费用归属表（快照）'!$F$4:$F$16,MATCH(D38,'费用归属表（快照）'!$A$4:$A$16,0)),"") | Q38: =IF(P38="","",P38-I38) | T38: =IF(D38="","",IFERROR(INDEX('费用归属表（快照）'!$C$4:$C$16,MATCH(D38,'费用归属表（快照）'!$A$4:$A$16,0)),"")) | U38: =IF(D38="","",IF(AND(D38="销售出库费用",B38="深圳星期九"),"永续供应中心 0010401",IF(AND(D38="原料入库费用",E38="小料"),"茶饮小料部 0030902",IFERROR(INDEX('费用归属表（快照）'!$D$4:$D$16,MATCH(D38,'费用归属表（快照）'!$A$4:$A$16,0)),"")))) | V38: =IF(D38="","",IFERROR(INDEX('费用归属表（快照）'!$B$4:$B$16,MATCH(D38,'费用归属表（快照）'!$A$4:$A$16,0)),"")) | W38: =IF(OR(E38="",AND(LEFT(T38,4)<>"6601",LEFT(T38,4)<>"6401")),"",IFERROR(IF(INDEX(选项!$I$2:$I$11,MATCH(E38,选项!$H$2:$H$11,0))="","",INDEX(选项!$I$2:$I$11,MATCH(E38,选项!$H$2:$H$11,0))),"")) | X38: =IF(OR(E38="",AND(LEFT(T38,4)<>"6601",LEFT(T38,4)<>"6401")),"",IFERROR(IF(INDEX(选项!$J$2:$J$11,MATCH(E38,选项!$H$2:$H$11,0))="","",INDEX(选项!$J$2:$J$11,MATCH(E38,选项!$H$2:$H$11,0))),""))
A39: 2026-07 | B39: 深圳星期零 | C39: 极鲜达 | D39: 销售出库费用 | E39: 零售 | G39: 月结 | I39: 12088.75 | J39: =IFERROR(INDEX(供应商列表!$F$4:$R$25,MATCH(C39,供应商列表!$A$4:$A$25,0),MATCH(D39,供应商列表!$F$3:$R$3,0)),"") | K39: =IFERROR(ROUND(I39/(1+J39),2),"") | L39: =IFERROR(I39-K39,"") | M39: =IFERROR(INDEX(供应商列表!$B$4:$B$25,MATCH(C39,供应商列表!$A$4:$A$25,0)),"") | N39: ="计提"&M39&(MID(A39,6,2)*1)&"月"&IFERROR(INDEX(供应商列表!$E$4:$E$25,MATCH(C39,供应商列表!$A$4:$A$25,0)),"线下")&IF(F39<>"",F39,IF(OR(E39="—",E39=""),"",E39))&IFERROR(INDEX('费用归属表（快照）'!$F$4:$F$16,MATCH(D39,'费用归属表（快照）'!$A$4:$A$16,0)),"") | Q39: =IF(P39="","",P39-I39) | T39: =IF(D39="","",IFERROR(INDEX('费用归属表（快照）'!$C$4:$C$16,MATCH(D39,'费用归属表（快照）'!$A$4:$A$16,0)),"")) | U39: =IF(D39="","",IF(AND(D39="销售出库费用",B39="深圳星期九"),"永续供应中心 0010401",IF(AND(D39="原料入库费用",E39="小料"),"茶饮小料部 0030902",IFERROR(INDEX('费用归属表（快照）'!$D$4:$D$16,MATCH(D39,'费用归属表（快照）'!$A$4:$A$16,0)),"")))) | V39: =IF(D39="","",IFERROR(INDEX('费用归属表（快照）'!$B$4:$B$16,MATCH(D39,'费用归属表（快照）'!$A$4:$A$16,0)),"")) | W39: =IF(OR(E39="",AND(LEFT(T39,4)<>"6601",LEFT(T39,4)<>"6401")),"",IFERROR(IF(INDEX(选项!$I$2:$I$11,MATCH(E39,选项!$H$2:$H$11,0))="","",INDEX(选项!$I$2:$I$11,MATCH(E39,选项!$H$2:$H$11,0))),"")) | X39: =IF(OR(E39="",AND(LEFT(T39,4)<>"6601",LEFT(T39,4)<>"6401")),"",IFERROR(IF(INDEX(选项!$J$2:$J$11,MATCH(E39,选项!$H$2:$H$11,0))="","",INDEX(选项!$J$2:$J$11,MATCH(E39,选项!$H$2:$H$11,0))),""))
A40: 2026-07 | B40: 深圳星期零 | C40: 极鲜达 | D40: 销售出库费用 | E40: 小料 | G40: 月结 | I40: 18086.67 | J40: =IFERROR(INDEX(供应商列表!$F$4:$R$25,MATCH(C40,供应商列表!$A$4:$A$25,0),MATCH(D40,供应商列表!$F$3:$R$3,0)),"") | K40: =IFERROR(ROUND(I40/(1+J40),2),"") | L40: =IFERROR(I40-K40,"") | M40: =IFERROR(INDEX(供应商列表!$B$4:$B$25,MATCH(C40,供应商列表!$A$4:$A$25,0)),"") | N40: ="计提"&M40&(MID(A40,6,2)*1)&"月"&IFERROR(INDEX(供应商列表!$E$4:$E$25,MATCH(C40,供应商列表!$A$4:$A$25,0)),"线下")&IF(F40<>"",F40,IF(OR(E40="—",E40=""),"",E40))&IFERROR(INDEX('费用归属表（快照）'!$F$4:$F$16,MATCH(D40,'费用归属表（快照）'!$A$4:$A$16,0)),"") | Q40: =IF(P40="","",P40-I40) | T40: =IF(D40="","",IFERROR(INDEX('费用归属表（快照）'!$C$4:$C$16,MATCH(D40,'费用归属表（快照）'!$A$4:$A$16,0)),"")) | U40: =IF(D40="","",IF(AND(D40="销售出库费用",B40="深圳星期九"),"永续供应中心 0010401",IF(AND(D40="原料入库费用",E40="小料"),"茶饮小料部 0030902",IFERROR(INDEX('费用归属表（快照）'!$D$4:$D$16,MATCH(D40,'费用归属表（快照）'!$A$4:$A$16,0)),"")))) | V40: =IF(D40="","",IFERROR(INDEX('费用归属表（快照）'!$B$4:$B$16,MATCH(D40,'费用归属表（快照）'!$A$4:$A$16,0)),"")) | W40: =IF(OR(E40="",AND(LEFT(T40,4)<>"6601",LEFT(T40,4)<>"6401")),"",IFERROR(IF(INDEX(选项!$I$2:$I$11,MATCH(E40,选项!$H$2:$H$11,0))="","",INDEX(选项!$I$2:$I$11,MATCH(E40,选项!$H$2:$H$11,0))),"")) | X40: =IF(OR(E40="",AND(LEFT(T40,4)<>"6601",LEFT(T40,4)<>"6401")),"",IFERROR(IF(INDEX(选项!$J$2:$J$11,MATCH(E40,选项!$H$2:$H$11,0))="","",INDEX(选项!$J$2:$J$11,MATCH(E40,选项!$H$2:$H$11,0))),""))
...

Sheet 做账去向表
A1: 做账去向表(本月费用准备做到哪个科目/哪个业务线/哪个部门——全公式自动,数据源=计提明细表维度列) 账期 2026-07
A2: 行=账证实证维度组合(2026 序时账 1229 行反推,共 27 种);金额=明细表按 主体×科目×部门×费用项目×产品分类×产品项目 六键汇总;新组合(人工改维度产生)落不进清单时,底部核对格≠0 提醒。
A3: 付款主体 | B3: 借方科目 | C3: 部门 | D3: 费用项目 | E3: 产品分类 | F3: 产品项目 | G3: 业务线(参考) | H3: 未税 | I3: 税额 | J3: 含税 | K3: 笔数 | L3: 账证月份
A4: 深圳星期零 | B4: 6601 销售费用 | C4: 永续物流中心 0011401 | D4: 出库运费 FYXM008.002其他物流费用002 | E4: CPFL007 | G4: 植物肉 | H4: =SUMIFS(计提明细表!$K$4:$K$59,计提明细表!$B$4:$B$59,$A4,计提明细表!$T$4:$T$59,$B4,计提明细表!$U$4:$U$59,$C4,计提明细表!$V$4:$V$59,$D4,计提明细表!$W$4:$W$59,$E4&"",计提明细表!$X$4:$X$59,$F4&"") | I4: =SUMIFS(计提明细表!$L$4:$L$59,计提明细表!$B$4:$B$59,$A4,计提明细表!$T$4:$T$59,$B4,计提明细表!$U$4:$U$59,$C4,计提明细表!$V$4:$V$59,$D4,计提明细表!$W$4:$W$59,$E4&"",计提明细表!$X$4:$X$59,$F4&"") | J4: =SUMIFS(计提明细表!$I$4:$I$59,计提明细表!$B$4:$B$59,$A4,计提明细表!$T$4:$T$59,$B4,计提明细表!$U$4:$U$59,$C4,计提明细表!$V$4:$V$59,$D4,计提明细表!$W$4:$W$59,$E4&"",计提明细表!$X$4:$X$59,$F4&"") | K4: =COUNTIFS(计提明细表!$B$4:$B$59,$A4,计提明细表!$T$4:$T$59,$B4,计提明细表!$U$4:$U$59,$C4,计提明细表!$V$4:$V$59,$D4,计提明细表!$W$4:$W$59,$E4&"",计提明细表!$X$4:$X$59,$F4&"") | L4: 1-6月
A5: 深圳星期零 | B5: 6601 销售费用 | C5: 永续物流中心 0011401 | D5: 出库运费 FYXM008.002其他物流费用002 | E5: CPFL010 | F5: CPXM017 | G5: 鲜食 | H5: =SUMIFS(计提明细表!$K$4:$K$59,计提明细表!$B$4:$B$59,$A5,计提明细表!$T$4:$T$59,$B5,计提明细表!$U$4:$U$59,$C5,计提明细表!$V$4:$V$59,$D5,计提明细表!$W$4:$W$59,$E5&"",计提明细表!$X$4:$X$59,$F5&"") | I5: =SUMIFS(计提明细表!$L$4:$L$59,计提明细表!$B$4:$B$59,$A5,计提明细表!$T$4:$T$59,$B5,计提明细表!$U$4:$U$59,$C5,计提明细表!$V$4:$V$59,$D5,计提明细表!$W$4:$W$59,$E5&"",计提明细表!$X$4:$X$59,$F5&"") | J5: =SUMIFS(计提明细表!$I$4:$I$59,计提明细表!$B$4:$B$59,$A5,计提明细表!$T$4:$T$59,$B5,计提明细表!$U$4:$U$59,$C5,计提明细表!$V$4:$V$59,$D5,计提明细表!$W$4:$W$59,$E5&"",计提明细表!$X$4:$X$59,$F5&"") | K5: =COUNTIFS(计提明细表!$B$4:$B$59,$A5,计提明细表!$T$4:$T$59,$B5,计提明细表!$U$4:$U$59,$C5,计提明细表!$V$4:$V$59,$D5,计提明细表!$W$4:$W$59,$E5&"",计提明细表!$X$4:$X$59,$F5&"") | L5: 1-6月
A6: 深圳星期零 | B6: 6601 销售费用 | C6: 永续物流中心 0011401 | D6: 出库运费 FYXM008.002其他物流费用002 | E6: CPFL011 | G6: 零售 | H6: =SUMIFS(计提明细表!$K$4:$K$59,计提明细表!$B$4:$B$59,$A6,计提明细表!$T$4:$T$59,$B6,计提明细表!$U$4:$U$59,$C6,计提明细表!$V$4:$V$59,$D6,计提明细表!$W$4:$W$59,$E6&"",计提明细表!$X$4:$X$59,$F6&"") | I6: =SUMIFS(计提明细表!$L$4:$L$59,计提明细表!$B$4:$B$59,$A6,计提明细表!$T$4:$T$59,$B6,计提明细表!$U$4:$U$59,$C6,计提明细表!$V$4:$V$59,$D6,计提明细表!$W$4:$W$59,$E6&"",计提明细表!$X$4:$X$59,$F6&"") | J6: =SUMIFS(计提明细表!$I$4:$I$59,计提明细表!$B$4:$B$59,$A6,计提明细表!$T$4:$T$59,$B6,计提明细表!$U$4:$U$59,$C6,计提明细表!$V$4:$V$59,$D6,计提明细表!$W$4:$W$59,$E6&"",计提明细表!$X$4:$X$59,$F6&"") | K6: =COUNTIFS(计提明细表!$B$4:$B$59,$A6,计提明细表!$T$4:$T$59,$B6,计提明细表!$U$4:$U$59,$C6,计提明细表!$V$4:$V$59,$D6,计提明细表!$W$4:$W$59,$E6&"",计提明细表!$X$4:$X$59,$F6&"") | L6: 1-6月
A7: 深圳星期零 | B7: 6601 销售费用 | C7: 永续物流中心 0011401 | D7: 出库运费 FYXM008.002其他物流费用002 | E7: CPFL011 | F7: CPXM017 | G7: 山姆零售 | H7: =SUMIFS(计提明细表!$K$4:$K$59,计提明细表!$B$4:$B$59,$A7,计提明细表!$T$4:$T$59,$B7,计提明细表!$U$4:$U$59,$C7,计提明细表!$V$4:$V$59,$D7,计提明细表!$W$4:$W$59,$E7&"",计提明细表!$X$4:$X$59,$F7&"") | I7: =SUMIFS(计提明细表!$L$4:$L$59,计提明细表!$B$4:$B$59,$A7,计提明细表!$T$4:$T$59,$B7,计提明细表!$U$4:$U$59,$C7,计提明细表!$V$4:$V$59,$D7,计提明细表!$W$4:$W$59,$E7&"",计提明细表!$X$4:$X$59,$F7&"") | J7: =SUMIFS(计提明细表!$I$4:$I$59,计提明细表!$B$4:$B$59,$A7,计提明细表!$T$4:$T$59,$B7,计提明细表!$U$4:$U$59,$C7,计提明细表!$V$4:$V$59,$D7,计提明细表!$W$4:$W$59,$E7&"",计提明细表!$X$4:$X$59,$F7&"") | K7: =COUNTIFS(计提明细表!$B$4:$B$59,$A7,计提明细表!$T$4:$T$59,$B7,计提明细表!$U$4:$U$59,$C7,计提明细表!$V$4:$V$59,$D7,计提明细表!$W$4:$W$59,$E7&"",计提明细表!$X$4:$X$59,$F7&"") | L7: 1-6月
A8: 深圳星期零 | B8: 6601 销售费用 | C8: 永续物流中心 0011401 | D8: 出库运费 FYXM008.002其他物流费用002 | E8: CPFL008 | G8: 豆蛋制品 | H8: =SUMIFS(计提明细表!$K$4:$K$59,计提明细表!$B$4:$B$59,$A8,计提明细表!$T$4:$T$59,$B8,计提明细表!$U$4:$U$59,$C8,计提明细表!$V$4:$V$59,$D8,计提明细表!$W$4:$W$59,$E8&"",计提明细表!$X$4:$X$59,$F8&"") | I8: =SUMIFS(计提明细表!$L$4:$L$59,计提明细表!$B$4:$B$59,$A8,计提明细表!$T$4:$T$59,$B8,计提明细表!$U$4:$U$59,$C8,计提明细表!$V$4:$V$59,$D8,计提明细表!$W$4:$W$59,$E8&"",计提明细表!$X$4:$X$59,$F8&"") | J8: =SUMIFS(计提明细表!$I$4:$I$59,计提明细表!$B$4:$B$59,$A8,计提明细表!$T$4:$T$59,$B8,计提明细表!$U$4:$U$59,$C8,计提明细表!$V$4:$V$59,$D8,计提明细表!$W$4:$W$59,$E8&"",计提明细表!$X$4:$X$59,$F8&"") | K8: =COUNTIFS(计提明细表!$B$4:$B$59,$A8,计提明细表!$T$4:$T$59,$B8,计提明细表!$U$4:$U$59,$C8,计提明细表!$V$4:$V$59,$D8,计提明细表!$W$4:$W$59,$E8&"",计提明细表!$X$4:$X$59,$F8&"") | L8: 1-6月
A9: 深圳星期零 | B9: 6601 销售费用 | C9: 永续物流中心 0011401 | D9: 出库运费 FYXM008.002其他物流费用002 | E9: CPFL009 | G9: 小料 | H9: =SUMIFS(计提明细表!$K$4:$K$59,计提明细表!$B$4:$B$59,$A9,计提明细表!$T$4:$T$59,$B9,计提明细表!$U$4:$U$59,$C9,计提明细表!$V$4:$V$59,$D9,计提明细表!$W$4:$W$59,$E9&"",计提明细表!$X$4:$X$59,$F9&"") | I9: =SUMIFS(计提明细表!$L$4:$L$59,计提明细表!$B$4:$B$59,$A9,计提明细表!$T$4:$T$59,$B9,计提明细表!$U$4:$U$59,$C9,计提明细表!$V$4:$V$59,$D9,计提明细表!$W$4:$W$59,$E9&"",计提明细表!$X$4:$X$59,$F9&"") | J9: =SUMIFS(计提明细表!$I$4:$I$59,计提明细表!$B$4:$B$59,$A9,计提明细表!$T$4:$T$59,$B9,计提明细表!$U$4:$U$59,$C9,计提明细表!$V$4:$V$59,$D9,计提明细表!$W$4:$W$59,$E9&"",计提明细表!$X$4:$X$59,$F9&"") | K9: =COUNTIFS(计提明细表!$B$4:$B$59,$A9,计提明细表!$T$4:$T$59,$B9,计提明细表!$U$4:$U$59,$C9,计提明细表!$V$4:$V$59,$D9,计提明细表!$W$4:$W$59,$E9&"",计提明细表!$X$4:$X$59,$F9&"") | L9: 1-6月
A10: 深圳星期零 | B10: 6601 销售费用 | C10: 永续物流中心 0011401 | D10: 出库运费 FYXM008.002其他物流费用002 | E10: CPFL002 | G10: 电商 | H10: =SUMIFS(计提明细表!$K$4:$K$59,计提明细表!$B$4:$B$59,$A10,计提明细表!$T$4:$T$59,$B10,计提明细表!$U$4:$U$59,$C10,计提明细表!$V$4:$V$59,$D10,计提明细表!$W$4:$W$59,$E10&"",计提明细表!$X$4:$X$59,$F10&"") | I10: =SUMIFS(计提明细表!$L$4:$L$59,计提明细表!$B$4:$B$59,$A10,计提明细表!$T$4:$T$59,$B10,计提明细表!$U$4:$U$59,$C10,计提明细表!$V$4:$V$59,$D10,计提明细表!$W$4:$W$59,$E10&"",计提明细表!$X$4:$X$59,$F10&"") | J10: =SUMIFS(计提明细表!$I$4:$I$59,计提明细表!$B$4:$B$59,$A10,计提明细表!$T$4:$T$59,$B10,计提明细表!$U$4:$U$59,$C10,计提明细表!$V$4:$V$59,$D10,计提明细表!$W$4:$W$59,$E10&"",计提明细表!$X$4:$X$59,$F10&"") | K10: =COUNTIFS(计提明细表!$B$4:$B$59,$A10,计提明细表!$T$4:$T$59,$B10,计提明细表!$U$4:$U$59,$C10,计提明细表!$V$4:$V$59,$D10,计提明细表!$W$4:$W$59,$E10&"",计提明细表!$X$4:$X$59,$F10&"") | L10: 1-6月
A11: 深圳星期零 | B11: 6601 销售费用 | C11: 永续物流中心 0011401 | D11: 出库运费 FYXM008.002其他物流费用002 | E11: CPFL013 | F11: CPXM022 | G11: kikiherb | H11: =SUMIFS(计提明细表!$K$4:$K$59,计提明细表!$B$4:$B$59,$A11,计提明细表!$T$4:$T$59,$B11,计提明细表!$U$4:$U$59,$C11,计提明细表!$V$4:$V$59,$D11,计提明细表!$W$4:$W$59,$E11&"",计提明细表!$X$4:$X$59,$F11&"") | I11: =SUMIFS(计提明细表!$L$4:$L$59,计提明细表!$B$4:$B$59,$A11,计提明细表!$T$4:$T$59,$B11,计提明细表!$U$4:$U$59,$C11,计提明细表!$V$4:$V$59,$D11,计提明细表!$W$4:$W$59,$E11&"",计提明细表!$X$4:$X$59,$F11&"") | J11: =SUMIFS(计提明细表!$I$4:$I$59,计提明细表!$B$4:$B$59,$A11,计提明细表!$T$4:$T$59,$B11,计提明细表!$U$4:$U$59,$C11,计提明细表!$V$4:$V$59,$D11,计提明细表!$W$4:$W$59,$E11&"",计提明细表!$X$4:$X$59,$F11&"") | K11: =COUNTIFS(计提明细表!$B$4:$B$59,$A11,计提明细表!$T$4:$T$59,$B11,计提明细表!$U$4:$U$59,$C11,计提明细表!$V$4:$V$59,$D11,计提明细表!$W$4:$W$59,$E11&"",计提明细表!$X$4:$X$59,$F11&"") | L11: 6月起
A12: 深圳星期零 | B12: 6601 销售费用 | C12: 永续物流中心 0011401 | D12: 货物仓储费 FYXM008.002其他物流费用001 | E12: CPFL010 | F12: CPXM017 | G12: 鲜食 | H12: =SUMIFS(计提明细表!$K$4:$K$59,计提明细表!$B$4:$B$59,$A12,计提明细表!$T$4:$T$59,$B12,计提明细表!$U$4:$U$59,$C12,计提明细表!$V$4:$V$59,$D12,计提明细表!$W$4:$W$59,$E12&"",计提明细表!$X$4:$X$59,$F12&"") | I12: =SUMIFS(计提明细表!$L$4:$L$59,计提明细表!$B$4:$B$59,$A12,计提明细表!$T$4:$T$59,$B12,计提明细表!$U$4:$U$59,$C12,计提明细表!$V$4:$V$59,$D12,计提明细表!$W$4:$W$59,$E12&"",计提明细表!$X$4:$X$59,$F12&"") | J12: =SUMIFS(计提明细表!$I$4:$I$59,计提明细表!$B$4:$B$59,$A12,计提明细表!$T$4:$T$59,$B12,计提明细表!$U$4:$U$59,$C12,计提明细表!$V$4:$V$59,$D12,计提明细表!$W$4:$W$59,$E12&"",计提明细表!$X$4:$X$59,$F12&"") | K12: =COUNTIFS(计提明细表!$B$4:$B$59,$A12,计提明细表!$T$4:$T$59,$B12,计提明细表!$U$4:$U$59,$C12,计提明细表!$V$4:$V$59,$D12,计提明细表!$W$4:$W$59,$E12&"",计提明细表!$X$4:$X$59,$F12&"") | L12: 3-4月
